Workbook

Sheet TODAY
B2: CHIP EXCHANGE
B4: Date | C4: =round(now(),0)-0.5-2 -> 46115.5 | E4: Status
B5: Start | C5: =IFERROR(__xludf.DUMMYFUNCTION("if(max(FORM!A2:A1891)>=C4,MIN(filter(FORM!A2:A1891,FORM!A2:A1891>C4)),"""")"),"") | E5: =if(B15-D15=0,"จบเกมส์","กำลังเล่น") -> จบเกมส์
B6: End | C6: =IFERROR(__xludf.DUMMYFUNCTION("MAX(filter(FORM!A2:A1891,FORM!A2:A1891<(C4+1),FORM!C2:C1891=""Return""))"),46103.179210891205) -> 46103.179
B8: PLAYER | C8: =IFERROR(__xludf.DUMMYFUNCTION("transpose(unique(filter(FORM!B2:B1891,FORM!A2:A1891>C4)))"),"#N/A") -> #N/A
B9: Buy | C9: =sumifs(FORM!$D$2:$D1891,FORM!$C$2:$C1891,$B9,FORM!$B$2:$B1891,C$8,FORM!$A$2:$A1891,">="&$C$5,FORM!$A$2:$A1891,"<="&$C$5+1) -> 0 | D9: =sumifs(FORM!$D$2:$D1891,FORM!$C$2:$C1891,$B9,FORM!$B$2:$B1891,D$8,FORM!$A$2:$A1891,">="&$C$5,FORM!$A$2:$A1891,"<="&$C$5+1) -> 0 | E9: =sumifs(FORM!$D$2:$D1891,FORM!$C$2:$C1891,$B9,FORM!$B$2:$B1891,E$8,FORM!$A$2:$A1891,">="&$C$5,FORM!$A$2:$A1891,"<="&$C$5+1) -> 0 | F9: =sumifs(FORM!$D$2:$D1891,FORM!$C$2:$C1891,$B9,FORM!$B$2:$B1891,F$8,FORM!$A$2:$A1891,">="&$C$5,FORM!$A$2:$A1891,"<="&$C$5+1) -> 0 | G9: =sumifs(FORM!$D$2:$D1891,FORM!$C$2:$C1891,$B9,FORM!$B$2:$B1891,G$8,FORM!$A$2:$A1891,">="&$C$5,FORM!$A$2:$A1891,"<="&$C$5+1) -> 0 | H9: =sumifs(FORM!$D$2:$D1891,FORM!$C$2:$C1891,$B9,FORM!$B$2:$B1891,H$8,FORM!$A$2:$A1891,">="&$C$5,FORM!$A$2:$A1891,"<="&$C$5+1) -> 0 | I9: =sumifs(FORM!$D$2:$D1891,FORM!$C$2:$C1891,$B9,FORM!$B$2:$B1891,I$8,FORM!$A$2:$A1891,">="&$C$5,FORM!$A$2:$A1891,"<="&$C$5+1) -> 0 | J9: =sumifs(FORM!$D$2:$D1891,FORM!$C$2:$C1891,$B9,FORM!$B$2:$B1891,J$8,FORM!$A$2:$A1891,">="&$C$5,FORM!$A$2:$A1891,"<="&$C$5+1) -> 0 | ... L9: =sumifs(FORM!$D$2:$D1891,FORM!$C$2:$C1891,$B9,FORM!$B$2:$B1891,L$8,FORM!$A$2:$A1891,">="&$C$5,FORM!$A$2:$A1891,"<="&$C$5+1) -> 0
B10: Return | C10: =sumifs(FORM!$D$2:$D1891,FORM!$C$2:$C1891,$B10,FORM!$B$2:$B1891,C$8,FORM!$A$2:$A1891,">="&$C$5,FORM!$A$2:$A1891,"<="&$C$5+1) -> 0 | D10: =sumifs(FORM!$D$2:$D1891,FORM!$C$2:$C1891,$B10,FORM!$B$2:$B1891,D$8,FORM!$A$2:$A1891,">="&$C$5,FORM!$A$2:$A1891,"<="&$C$5+1) -> 0 | E10: =sumifs(FORM!$D$2:$D1891,FORM!$C$2:$C1891,$B10,FORM!$B$2:$B1891,E$8,FORM!$A$2:$A1891,">="&$C$5,FORM!$A$2:$A1891,"<="&$C$5+1) -> 0 | F10: =sumifs(FORM!$D$2:$D1891,FORM!$C$2:$C1891,$B10,FORM!$B$2:$B1891,F$8,FORM!$A$2:$A1891,">="&$C$5,FORM!$A$2:$A1891,"<="&$C$5+1) -> 0 | G10: =sumifs(FORM!$D$2:$D1891,FORM!$C$2:$C1891,$B10,FORM!$B$2:$B1891,G$8,FORM!$A$2:$A1891,">="&$C$5,FORM!$A$2:$A1891,"<="&$C$5+1) -> 0 | H10: =sumifs(FORM!$D$2:$D1891,FORM!$C$2:$C1891,$B10,FORM!$B$2:$B1891,H$8,FORM!$A$2:$A1891,">="&$C$5,FORM!$A$2:$A1891,"<="&$C$5+1) -> 0 | I10: =sumifs(FORM!$D$2:$D1891,FORM!$C$2:$C1891,$B10,FORM!$B$2:$B1891,I$8,FORM!$A$2:$A1891,">="&$C$5,FORM!$A$2:$A1891,"<="&$C$5+1) -> 0 | J10: =sumifs(FORM!$D$2:$D1891,FORM!$C$2:$C1891,$B10,FORM!$B$2:$B1891,J$8,FORM!$A$2:$A1891,">="&$C$5,FORM!$A$2:$A1891,"<="&$C$5+1) -> 0 | ... L10: =sumifs(FORM!$D$2:$D1891,FORM!$C$2:$C1891,$B10,FORM!$B$2:$B1891,L$8,FORM!$A$2:$A1891,">="&$C$5,FORM!$A$2:$A1891,"<="&$C$5+1) -> 0
B11: Balance | C11: =C10-C9 -> 0 | D11: =D10-D9 -> 0 | E11: =E10-E9 -> 0 | F11: =F10-F9 -> 0 | G11: =G10-G9 -> 0 | H11: =H10-H9 -> 0 | I11: =I10-I9 -> 0 | J11: =J10-J9 -> 0 | ... L11: =L10-L9 -> 0
B14: Total Buy | D14: Total Return
B15: =sum(C9:KG9) -> 0 | D15: =sum(C10:KG10) -> 0

Sheet FORM
A1: ประทับเวลา | B1: NAME | C1: TYPE | D1: AMOUNT (THB)
A2: 44835.852 | B2: Add | C2: Buy | D2: 200
A3: 44835.852 | B3: Max | C3: Buy | D3: 300
A4: 44835.852 | B4: Nuch | C4: Buy | D4: 200
A5: 44835.852 | B5: Champ | C5: Buy | D5: 200
A6: 44835.852 | B6: Tle | C6: Buy | D6: 200
A7: 44835.852 | B7: Fah | C7: Buy | D7: 200
A8: 44835.852 | B8: Wut | C8: Buy | D8: 200
A9: 44835.862 | B9: Max | C9: Buy | D9: 100
A10: 44835.862 | B10: Tle | C10: Buy | D10: 300
A11: 44835.87 | B11: Tle | C11: Buy | D11: 500
A12: 44835.893 | B12: Fah | C12: Buy | D12: 200
A13: 44835.896 | B13: Champ | C13: Buy | D13: 200
... A1365: 45241.114 | B1365: Petch | C1365: Buy | D1365: 100
A1366: 45241.15 | B1366: Petch | C1366: Return | D1366: 325 | I1366: {=if(F1366:F3194="","",G1366:G3194-H1366:H3194)}
A1367: 45241.168 | B1367: Tle | C1367: Buy | D1367: 500
A1368: 45241.262 | B1368: Add | C1368: Return | D1368: 204
A1369: 45241.263 | B1369: Aof | C1369: Return | D1369: 1125
A1370: 45241.263 | B1370: Wut | C1370: Return | D1370: 1080
A1371: 45241.264 | B1371: Tle | C1371: Return | D1371: 876
A1372: 45241.264 | B1372: Fah | C1372: Return | D1372: 103
A1373: 45248.865 | B1373: Add | C1373: Buy | D1373: 1000
A1374: 45248.865 | B1374: Max | C1374: Buy | D1374: 1000
A1375: 45248.865 | B1375: Petch | C1375: Buy | D1375: 1000
A1376: 45248.865 | B1376: Wut | C1376: Buy | D1376: 1000
A1377: 45248.894 | B1377: Wut | C1377: Buy | D1377: 1000
A1378: 45248.927 | B1378: Add | C1378: Return | D1378: 500
... A2582: 45626.251 | B2582: Aof | C2582: Return | D2582: 16240
A2583: =E2583-1 -> 45632.849 | B2583: Add | C2583: Buy | D2583: 2000 | E2583: 45633.849
A2584: =E2584-1 -> 45632.849 | B2584: Wut | C2584: Buy | D2584: 2000 | E2584: 45633.849
A2585: =E2585-1 -> 45632.849 | B2585: Petch | C2585: Buy | D2585: 2000 | E2585: 45633.849
A2586: =E2586-1 -> 45632.85 | B2586: Max | C2586: Buy | D2586: 2000 | E2586: 45633.85
A2587: =E2587-1 -> 45632.85 | B2587: Nuch | C2587: Buy | D2587: 2000 | E2587: 45633.85
A2588: =E2588-1 -> 45632.85 | B2588: Tee | C2588: Buy | D2588: 2000 | E2588: 45633.85
A2589: =E2589-1 -> 45632.859 | B2589: Wut | C2589: Buy | D2589: 2000 | E2589: 45633.859
A2590: =E2590-1 -> 45632.859 | B2590: Max | C2590: Buy | D2590: 2000 | E2590: 45633.859
A2591: =E2591-1 -> 45632.864 | B2591: Max | C2591: Buy | D2591: 3000 | E2591: 45633.864
A2592: =E2592-1 -> 45632.868 | B2592: Wut | C2592: Buy | D2592: 3000 | E2592: 45633.868
A2593: =E2593-1 -> 45632.89 | B2593: Wut | C2593: Buy | D2593: 3000 | E2593: 45633.89
A2594: =E2594-1 -> 45632.924 | B2594: Wut | C2594: Buy | D2594: 3000 | E2594: 45633.924
...

Sheet DAILY
B2: DATE | C2: Rate (1:X) | D2: {=transpose(unique(FORM!B2:B459))} -> Add | E2: Max | F2: Nuch | G2: Champ | H2: Tle | I2: Fah | J2: Wut | K2: Parn | L2: Game | M2: Aof | N2: Top | O2: Guest | P2: Petch | Q2: Foam | R2: เหน่ง | S2: Tee | T2: Dream | U2: Boss
B3: {=unique(ROUND(FORM!A2:A3190,0)-1)} -> 44835 | C3: 10 | D3: =sumifs(FORM!$D$2:$D459,FORM!$C$2:$C459,TODAY!$B$10,FORM!$B$2:$B459,D$2,FORM!$A$2:$A459,">"&$B3+0.5,FORM!$A$2:$A459,"<"&$B3+1.5)-sumifs(FORM!$D$2:$D459,FORM!$C$2:$C459,TODAY!$B$9,FORM!$B$2:$B459,D$2,FORM!$A$2:$A459,">"&$B3+0.5,FORM!$A$2:$A459,"<"&$B3+1.5) -> 540 | E3: =sumifs(FORM!$D$2:$D459,FORM!$C$2:$C459,TODAY!$B$10,FORM!$B$2:$B459,E$2,FORM!$A$2:$A459,">"&$B3+0.5,FORM!$A$2:$A459,"<"&$B3+1.5)-sumifs(FORM!$D$2:$D459,FORM!$C$2:$C459,TODAY!$B$9,FORM!$B$2:$B459,E$2,FORM!$A$2:$A459,">"&$B3+0.5,FORM!$A$2:$A459,"<"&$B3+1.5) -> -600 | F3: =sumifs(FORM!$D$2:$D459,FORM!$C$2:$C459,TODAY!$B$10,FORM!$B$2:$B459,F$2,FORM!$A$2:$A459,">"&$B3+0.5,FORM!$A$2:$A459,"<"&$B3+1.5)-sumifs(FORM!$D$2:$D459,FORM!$C$2:$C459,TODAY!$B$9,FORM!$B$2:$B459,F$2,FORM!$A$2:$A459,">"&$B3+0.5,FORM!$A$2:$A459,"<"&$B3+1.5) -> 407 | G3: =sumifs(FORM!$D$2:$D459,FORM!$C$2:$C459,TODAY!$B$10,FORM!$B$2:$B459,G$2,FORM!$A$2:$A459,">"&$B3+0.5,FORM!$A$2:$A459,"<"&$B3+1.5)-sumifs(FORM!$D$2:$D459,FORM!$C$2:$C459,TODAY!$B$9,FORM!$B$2:$B459,G$2,FORM!$A$2:$A459,">"&$B3+0.5,FORM!$A$2:$A459,"<"&$B3+1.5) -> -1059 | H3: =sumifs(FORM!$D$2:$D459,FORM!$C$2:$C459,TODAY!$B$10,FORM!$B$2:$B459,H$2,FORM!$A$2:$A459,">"&$B3+0.5,FORM!$A$2:$A459,"<"&$B3+1.5)-sumifs(FORM!$D$2:$D459,FORM!$C$2:$C459,TODAY!$B$9,FORM!$B$2:$B459,H$2,FORM!$A$2:$A459,">"&$B3+0.5,FORM!$A$2:$A459,"<"&$B3+1.5) -> -579 | I3: =sumifs(FORM!$D$2:$D459,FORM!$C$2:$C459,TODAY!$B$10,FORM!$B$2:$B459,I$2,FORM!$A$2:$A459,">"&$B3+0.5,FORM!$A$2:$A459,"<"&$B3+1.5)-sumifs(FORM!$D$2:$D459,FORM!$C$2:$C459,TODAY!$B$9,FORM!$B$2:$B459,I$2,FORM!$A$2:$A459,">"&$B3+0.5,FORM!$A$2:$A459,"<"&$B3+1.5) -> 824 | J3: =sumifs(FORM!$D$2:$D459,FORM!$C$2:$C459,TODAY!$B$10,FORM!$B$2:$B459,J$2,FORM!$A$2:$A459,">"&$B3+0.5,FORM!$A$2:$A459,"<"&$B3+1.5)-sumifs(FORM!$D$2:$D459,FORM!$C$2:$C459,TODAY!$B$9,FORM!$B$2:$B459,J$2,FORM!$A$2:$A459,">"&$B3+0.5,FORM!$A$2:$A459,"<"&$B3+1.5) -> 467 | K3: =sumifs(FORM!$D$2:$D459,FORM!$C$2:$C459,TODAY!$B$10,FORM!$B$2:$B459,K$2,FORM!$A$2:$A459,">"&$B3+0.5,FORM!$A$2:$A459,"<"&$B3+1.5)-sumifs(FORM!$D$2:$D459,FORM!$C$2:$C459,TODAY!$B$9,FORM!$B$2:$B459,K$2,FORM!$A$2:$A459,">"&$B3+0.5,FORM!$A$2:$A459,"<"&$B3+1.5) -> 0 | ... P3: =sumifs(FORM!$D$2:$D459,FORM!$C$2:$C459,TODAY!$B$10,FORM!$B$2:$B459,P$2,FORM!$A$2:$A459,">"&$B3+0.5,FORM!$A$2:$A459,"<"&$B3+1.5)-sumifs(FORM!$D$2:$D459,FORM!$C$2:$C459,TODAY!$B$9,FORM!$B$2:$B459,P$2,FORM!$A$2:$A459,">"&$B3+0.5,FORM!$A$2:$A459,"<"&$B3+1.5) -> 0 | Q3: 0 | R3: 0 | S3: 0 | T3: 0 | U3: =if(or($C3="",U$2=""),"",(sumifs(FORM!$D$2:$D459,FORM!$C$2:$C459,TODAY!$B$10,FORM!$B$2:$B459,U$2,FORM!$A$2:$A459,">"&$B3+0.5,FORM!$A$2:$A459,"<"&$B3+1.5)-sumifs(FORM!$D$2:$D459,FORM!$C$2:$C459,TODAY!$B$9,FORM!$B$2:$B459,U$2,FORM!$A$2:$A459,">"&$B3+0.5,FORM!$A$2:$A459,"<"&$B3+1.5))/$C3) -> 0
B4: 44836 | C4: 10 | D4: =sumifs(FORM!$D$2:$D459,FORM!$C$2:$C459,TODAY!$B$10,FORM!$B$2:$B459,D$2,FORM!$A$2:$A459,">"&$B4+0.5,FORM!$A$2:$A459,"<"&$B4+1.5)-sumifs(FORM!$D$2:$D459,FORM!$C$2:$C459,TODAY!$B$9,FORM!$B$2:$B459,D$2,FORM!$A$2:$A459,">"&$B4+0.5,FORM!$A$2:$A459,"<"&$B4+1.5) -> -700 | E4: =sumifs(FORM!$D$2:$D459,FORM!$C$2:$C459,TODAY!$B$10,FORM!$B$2:$B459,E$2,FORM!$A$2:$A459,">"&$B4+0.5,FORM!$A$2:$A459,"<"&$B4+1.5)-sumifs(FORM!$D$2:$D459,FORM!$C$2:$C459,TODAY!$B$9,FORM!$B$2:$B459,E$2,FORM!$A$2:$A459,">"&$B4+0.5,FORM!$A$2:$A459,"<"&$B4+1.5) -> 106 | F4: =sumifs(FORM!$D$2:$D459,FORM!$C$2:$C459,TODAY!$B$10,FORM!$B$2:$B459,F$2,FORM!$A$2:$A459,">"&$B4+0.5,FORM!$A$2:$A459,"<"&$B4+1.5)-sumifs(FORM!$D$2:$D459,FORM!$C$2:$C459,TODAY!$B$9,FORM!$B$2:$B459,F$2,FORM!$A$2:$A459,">"&$B4+0.5,FORM!$A$2:$A459,"<"&$B4+1.5) -> -80 | G4: =sumifs(FORM!$D$2:$D459,FORM!$C$2:$C459,TODAY!$B$10,FORM!$B$2:$B459,G$2,FORM!$A$2:$A459,">"&$B4+0.5,FORM!$A$2:$A459,"<"&$B4+1.5)-sumifs(FORM!$D$2:$D459,FORM!$C$2:$C459,TODAY!$B$9,FORM!$B$2:$B459,G$2,FORM!$A$2:$A459,">"&$B4+0.5,FORM!$A$2:$A459,"<"&$B4+1.5) -> 64 | H4: =sumifs(FORM!$D$2:$D459,FORM!$C$2:$C459,TODAY!$B$10,FORM!$B$2:$B459,H$2,FORM!$A$2:$A459,">"&$B4+0.5,FORM!$A$2:$A459,"<"&$B4+1.5)-sumifs(FORM!$D$2:$D459,FORM!$C$2:$C459,TODAY!$B$9,FORM!$B$2:$B459,H$2,FORM!$A$2:$A459,">"&$B4+0.5,FORM!$A$2:$A459,"<"&$B4+1.5) -> 607 | I4: =sumifs(FORM!$D$2:$D459,FORM!$C$2:$C459,TODAY!$B$10,FORM!$B$2:$B459,I$2,FORM!$A$2:$A459,">"&$B4+0.5,FORM!$A$2:$A459,"<"&$B4+1.5)-sumifs(FORM!$D$2:$D459,FORM!$C$2:$C459,TODAY!$B$9,FORM!$B$2:$B459,I$2,FORM!$A$2:$A459,">"&$B4+0.5,FORM!$A$2:$A459,"<"&$B4+1.5) -> 91 | J4: =sumifs(FORM!$D$2:$D459,FORM!$C$2:$C459,TODAY!$B$10,FORM!$B$2:$B459,J$2,FORM!$A$2:$A459,">"&$B4+0.5,FORM!$A$2:$A459,"<"&$B4+1.5)-sumifs(FORM!$D$2:$D459,FORM!$C$2:$C459,TODAY!$B$9,FORM!$B$2:$B459,J$2,FORM!$A$2:$A459,">"&$B4+0.5,FORM!$A$2:$A459,"<"&$B4+1.5) -> -88 | K4: =sumifs(FORM!$D$2:$D459,FORM!$C$2:$C459,TODAY!$B$10,FORM!$B$2:$B459,K$2,FORM!$A$2:$A459,">"&$B4+0.5,FORM!$A$2:$A459,"<"&$B4+1.5)-sumifs(FORM!$D$2:$D459,FORM!$C$2:$C459,TODAY!$B$9,FORM!$B$2:$B459,K$2,FORM!$A$2:$A459,">"&$B4+0.5,FORM!$A$2:$A459,"<"&$B4+1.5) -> 0 | ... P4: =sumifs(FORM!$D$2:$D459,FORM!$C$2:$C459,TODAY!$B$10,FORM!$B$2:$B459,P$2,FORM!$A$2:$A459,">"&$B4+0.5,FORM!$A$2:$A459,"<"&$B4+1.5)-sumifs(FORM!$D$2:$D459,FORM!$C$2:$C459,TODAY!$B$9,FORM!$B$2:$B459,P$2,FORM!$A$2:$A459,">"&$B4+0.5,FORM!$A$2:$A459,"<"&$B4+1.5) -> 0 | Q4: 0 | R4: 0 | S4: 0 | T4: 0 | U4: =if(or($C4="",U$2=""),"",(sumifs(FORM!$D$2:$D459,FORM!$C$2:$C459,TODAY!$B$10,FORM!$B$2:$B459,U$2,FORM!$A$2:$A459,">"&$B4+0.5,FORM!$A$2:$A459,"<"&$B4+1.5)-sumifs(FORM!$D$2:$D459,FORM!$C$2:$C459,TODAY!$B$9,FORM!$B$2:$B459,U$2,FORM!$A$2:$A459,">"&$B4+0.5,FORM!$A$2:$A459,"<"&$B4+1.5))/$C4) -> 0
B5: 44837 | C5: 10 | D5: =sumifs(FORM!$D$2:$D459,FORM!$C$2:$C459,TODAY!$B$10,FORM!$B$2:$B459,D$2,FORM!$A$2:$A459,">"&$B5+0.5,FORM!$A$2:$A459,"<"&$B5+1.5)-sumifs(FORM!$D$2:$D459,FORM!$C$2:$C459,TODAY!$B$9,FORM!$B$2:$B459,D$2,FORM!$A$2:$A459,">"&$B5+0.5,FORM!$A$2:$A459,"<"&$B5+1.5) -> 45 | E5: =sumifs(FORM!$D$2:$D459,FORM!$C$2:$C459,TODAY!$B$10,FORM!$B$2:$B459,E$2,FORM!$A$2:$A459,">"&$B5+0.5,FORM!$A$2:$A459,"<"&$B5+1.5)-sumifs(FORM!$D$2:$D459,FORM!$C$2:$C459,TODAY!$B$9,FORM!$B$2:$B459,E$2,FORM!$A$2:$A459,">"&$B5+0.5,FORM!$A$2:$A459,"<"&$B5+1.5) -> -400 | F5: =sumifs(FORM!$D$2:$D459,FORM!$C$2:$C459,TODAY!$B$10,FORM!$B$2:$B459,F$2,FORM!$A$2:$A459,">"&$B5+0.5,FORM!$A$2:$A459,"<"&$B5+1.5)-sumifs(FORM!$D$2:$D459,FORM!$C$2:$C459,TODAY!$B$9,FORM!$B$2:$B459,F$2,FORM!$A$2:$A459,">"&$B5+0.5,FORM!$A$2:$A459,"<"&$B5+1.5) -> 100 | G5: =sumifs(FORM!$D$2:$D459,FORM!$C$2:$C459,TODAY!$B$10,FORM!$B$2:$B459,G$2,FORM!$A$2:$A459,">"&$B5+0.5,FORM!$A$2:$A459,"<"&$B5+1.5)-sumifs(FORM!$D$2:$D459,FORM!$C$2:$C459,TODAY!$B$9,FORM!$B$2:$B459,G$2,FORM!$A$2:$A459,">"&$B5+0.5,FORM!$A$2:$A459,"<"&$B5+1.5) -> -50 | H5: =sumifs(FORM!$D$2:$D459,FORM!$C$2:$C459,TODAY!$B$10,FORM!$B$2:$B459,H$2,FORM!$A$2:$A459,">"&$B5+0.5,FORM!$A$2:$A459,"<"&$B5+1.5)-sumifs(FORM!$D$2:$D459,FORM!$C$2:$C459,TODAY!$B$9,FORM!$B$2:$B459,H$2,FORM!$A$2:$A459,">"&$B5+0.5,FORM!$A$2:$A459,"<"&$B5+1.5) -> 13 | I5: =sumifs(FORM!$D$2:$D459,FORM!$C$2:$C459,TODAY!$B$10,FORM!$B$2:$B459,I$2,FORM!$A$2:$A459,">"&$B5+0.5,FORM!$A$2:$A459,"<"&$B5+1.5)-sumifs(FORM!$D$2:$D459,FORM!$C$2:$C459,TODAY!$B$9,FORM!$B$2:$B459,I$2,FORM!$A$2:$A459,">"&$B5+0.5,FORM!$A$2:$A459,"<"&$B5+1.5) -> 292 | J5: =sumifs(FORM!$D$2:$D459,FORM!$C$2:$C459,TODAY!$B$10,FORM!$B$2:$B459,J$2,FORM!$A$2:$A459,">"&$B5+0.5,FORM!$A$2:$A459,"<"&$B5+1.5)-sumifs(FORM!$D$2:$D459,FORM!$C$2:$C459,TODAY!$B$9,FORM!$B$2:$B459,J$2,FORM!$A$2:$A459,">"&$B5+0.5,FORM!$A$2:$A459,"<"&$B5+1.5) -> 1100 | K5: =sumifs(FORM!$D$2:$D459,FORM!$C$2:$C459,TODAY!$B$10,FORM!$B$2:$B459,K$2,FORM!$A$2:$A459,">"&$B5+0.5,FORM!$A$2:$A459,"<"&$B5+1.5)-sumifs(FORM!$D$2:$D459,FORM!$C$2:$C459,TODAY!$B$9,FORM!$B$2:$B459,K$2,FORM!$A$2:$A459,">"&$B5+0.5,FORM!$A$2:$A459,"<"&$B5+1.5) -> -400 | ... P5: =sumifs(FORM!$D$2:$D459,FORM!$C$2:$C459,TODAY!$B$10,FORM!$B$2:$B459,P$2,FORM!$A$2:$A459,">"&$B5+0.5,FORM!$A$2:$A459,"<"&$B5+1.5)-sumifs(FORM!$D$2:$D459,FORM!$C$2:$C459,TODAY!$B$9,FORM!$B$2:$B459,P$2,FORM!$A$2:$A459,">"&$B5+0.5,FORM!$A$2:$A459,"<"&$B5+1.5) -> 0 | Q5: 0 | R5: 0 | S5: 0 | T5: 0 | U5: =if(or($C5="",U$2=""),"",(sumifs(FORM!$D$2:$D459,FORM!$C$2:$C459,TODAY!$B$10,FORM!$B$2:$B459,U$2,FORM!$A$2:$A459,">"&$B5+0.5,FORM!$A$2:$A459,"<"&$B5+1.5)-sumifs(FORM!$D$2:$D459,FORM!$C$2:$C459,TODAY!$B$9,FORM!$B$2:$B459,U$2,FORM!$A$2:$A459,">"&$B5+0.5,FORM!$A$2:$A459,"<"&$B5+1.5))/$C5) -> 0
B6: 44841 | C6: 10 | D6: =sumifs(FORM!$D$2:$D459,FORM!$C$2:$C459,TODAY!$B$10,FORM!$B$2:$B459,D$2,FORM!$A$2:$A459,">"&$B6+0.5,FORM!$A$2:$A459,"<"&$B6+1.5)-sumifs(FORM!$D$2:$D459,FORM!$C$2:$C459,TODAY!$B$9,FORM!$B$2:$B459,D$2,FORM!$A$2:$A459,">"&$B6+0.5,FORM!$A$2:$A459,"<"&$B6+1.5) -> 296 | E6: =sumifs(FORM!$D$2:$D459,FORM!$C$2:$C459,TODAY!$B$10,FORM!$B$2:$B459,E$2,FORM!$A$2:$A459,">"&$B6+0.5,FORM!$A$2:$A459,"<"&$B6+1.5)-sumifs(FORM!$D$2:$D459,FORM!$C$2:$C459,TODAY!$B$9,FORM!$B$2:$B459,E$2,FORM!$A$2:$A459,">"&$B6+0.5,FORM!$A$2:$A459,"<"&$B6+1.5) -> 1110 | F6: =sumifs(FORM!$D$2:$D459,FORM!$C$2:$C459,TODAY!$B$10,FORM!$B$2:$B459,F$2,FORM!$A$2:$A459,">"&$B6+0.5,FORM!$A$2:$A459,"<"&$B6+1.5)-sumifs(FORM!$D$2:$D459,FORM!$C$2:$C459,TODAY!$B$9,FORM!$B$2:$B459,F$2,FORM!$A$2:$A459,">"&$B6+0.5,FORM!$A$2:$A459,"<"&$B6+1.5) -> -400 | G6: =sumifs(FORM!$D$2:$D459,FORM!$C$2:$C459,TODAY!$B$10,FORM!$B$2:$B459,G$2,FORM!$A$2:$A459,">"&$B6+0.5,FORM!$A$2:$A459,"<"&$B6+1.5)-sumifs(FORM!$D$2:$D459,FORM!$C$2:$C459,TODAY!$B$9,FORM!$B$2:$B459,G$2,FORM!$A$2:$A459,">"&$B6+0.5,FORM!$A$2:$A459,"<"&$B6+1.5) -> -435 | H6: =sumifs(FORM!$D$2:$D459,FORM!$C$2:$C459,TODAY!$B$10,FORM!$B$2:$B459,H$2,FORM!$A$2:$A459,">"&$B6+0.5,FORM!$A$2:$A459,"<"&$B6+1.5)-sumifs(FORM!$D$2:$D459,FORM!$C$2:$C459,TODAY!$B$9,FORM!$B$2:$B459,H$2,FORM!$A$2:$A459,">"&$B6+0.5,FORM!$A$2:$A459,"<"&$B6+1.5) -> -443 | I6: =sumifs(FORM!$D$2:$D459,FORM!$C$2:$C459,TODAY!$B$10,FORM!$B$2:$B459,I$2,FORM!$A$2:$A459,">"&$B6+0.5,FORM!$A$2:$A459,"<"&$B6+1.5)-sumifs(FORM!$D$2:$D459,FORM!$C$2:$C459,TODAY!$B$9,FORM!$B$2:$B459,I$2,FORM!$A$2:$A459,">"&$B6+0.5,FORM!$A$2:$A459,"<"&$B6+1.5) -> 0 | J6: =sumifs(FORM!$D$2:$D459,FORM!$C$2:$C459,TODAY!$B$10,FORM!$B$2:$B459,J$2,FORM!$A$2:$A459,">"&$B6+0.5,FORM!$A$2:$A459,"<"&$B6+1.5)-sumifs(FORM!$D$2:$D459,FORM!$C$2:$C459,TODAY!$B$9,FORM!$B$2:$B459,J$2,FORM!$A$2:$A459,">"&$B6+0.5,FORM!$A$2:$A459,"<"&$B6+1.5) -> -128 | K6: =sumifs(FORM!$D$2:$D459,FORM!$C$2:$C459,TODAY!$B$10,FORM!$B$2:$B459,K$2,FORM!$A$2:$A459,">"&$B6+0.5,FORM!$A$2:$A459,"<"&$B6+1.5)-sumifs(FORM!$D$2:$D459,FORM!$C$2:$C459,TODAY!$B$9,FORM!$B$2:$B459,K$2,FORM!$A$2:$A459,">"&$B6+0.5,FORM!$A$2:$A459,"<"&$B6+1.5) -> 0 | ... P6: =sumifs(FORM!$D$2:$D459,FORM!$C$2:$C459,TODAY!$B$10,FORM!$B$2:$B459,P$2,FORM!$A$2:$A459,">"&$B6+0.5,FORM!$A$2:$A459,"<"&$B6+1.5)-sumifs(FORM!$D$2:$D459,FORM!$C$2:$C459,TODAY!$B$9,FORM!$B$2:$B459,P$2,FORM!$A$2:$A459,">"&$B6+0.5,FORM!$A$2:$A459,"<"&$B6+1.5) -> 0 | Q6: 0 | R6: 0 | S6: 0 | T6: 0 | U6: =if(or($C6="",U$2=""),"",(sumifs(FORM!$D$2:$D459,FORM!$C$2:$C459,TODAY!$B$10,FORM!$B$2:$B459,U$2,FORM!$A$2:$A459,">"&$B6+0.5,FORM!$A$2:$A459,"<"&$B6+1.5)-sumifs(FORM!$D$2:$D459,FORM!$C$2:$C459,TODAY!$B$9,FORM!$B$2:$B459,U$2,FORM!$A$2:$A459,">"&$B6+0.5,FORM!$A$2:$A459,"<"&$B6+1.5))/$C6) -> 0
B7: 44842 | C7: 10 | D7: =sumifs(FORM!$D$2:$D459,FORM!$C$2:$C459,TODAY!$B$10,FORM!$B$2:$B459,D$2,FORM!$A$2:$A459,">"&$B7+0.5,FORM!$A$2:$A459,"<"&$B7+1.5)-sumifs(FORM!$D$2:$D459,FORM!$C$2:$C459,TODAY!$B$9,FORM!$B$2:$B459,D$2,FORM!$A$2:$A459,">"&$B7+0.5,FORM!$A$2:$A459,"<"&$B7+1.5) -> 355 | E7: =sumifs(FORM!$D$2:$D459,FORM!$C$2:$C459,TODAY!$B$10,FORM!$B$2:$B459,E$2,FORM!$A$2:$A459,">"&$B7+0.5,FORM!$A$2:$A459,"<"&$B7+1.5)-sumifs(FORM!$D$2:$D459,FORM!$C$2:$C459,TODAY!$B$9,FORM!$B$2:$B459,E$2,FORM!$A$2:$A459,">"&$B7+0.5,FORM!$A$2:$A459,"<"&$B7+1.5) -> -300 | F7: =sumifs(FORM!$D$2:$D459,FORM!$C$2:$C459,TODAY!$B$10,FORM!$B$2:$B459,F$2,FORM!$A$2:$A459,">"&$B7+0.5,FORM!$A$2:$A459,"<"&$B7+1.5)-sumifs(FORM!$D$2:$D459,FORM!$C$2:$C459,TODAY!$B$9,FORM!$B$2:$B459,F$2,FORM!$A$2:$A459,">"&$B7+0.5,FORM!$A$2:$A459,"<"&$B7+1.5) -> -154 | G7: =sumifs(FORM!$D$2:$D459,FORM!$C$2:$C459,TODAY!$B$10,FORM!$B$2:$B459,G$2,FORM!$A$2:$A459,">"&$B7+0.5,FORM!$A$2:$A459,"<"&$B7+1.5)-sumifs(FORM!$D$2:$D459,FORM!$C$2:$C459,TODAY!$B$9,FORM!$B$2:$B459,G$2,FORM!$A$2:$A459,">"&$B7+0.5,FORM!$A$2:$A459,"<"&$B7+1.5) -> 258 | H7: =sumifs(FORM!$D$2:$D459,FORM!$C$2:$C459,TODAY!$B$10,FORM!$B$2:$B459,H$2,FORM!$A$2:$A459,">"&$B7+0.5,FORM!$A$2:$A459,"<"&$B7+1.5)-sumifs(FORM!$D$2:$D459,FORM!$C$2:$C459,TODAY!$B$9,FORM!$B$2:$B459,H$2,FORM!$A$2:$A459,">"&$B7+0.5,FORM!$A$2:$A459,"<"&$B7+1.5) -> 200 | I7: =sumifs(FORM!$D$2:$D459,FORM!$C$2:$C459,TODAY!$B$10,FORM!$B$2:$B459,I$2,FORM!$A$2:$A459,">"&$B7+0.5,FORM!$A$2:$A459,"<"&$B7+1.5)-sumifs(FORM!$D$2:$D459,FORM!$C$2:$C459,TODAY!$B$9,FORM!$B$2:$B459,I$2,FORM!$A$2:$A459,">"&$B7+0.5,FORM!$A$2:$A459,"<"&$B7+1.5) -> 441 | J7: =sumifs(FORM!$D$2:$D459,FORM!$C$2:$C459,TODAY!$B$10,FORM!$B$2:$B459,J$2,FORM!$A$2:$A459,">"&$B7+0.5,FORM!$A$2:$A459,"<"&$B7+1.5)-sumifs(FORM!$D$2:$D459,FORM!$C$2:$C459,TODAY!$B$9,FORM!$B$2:$B459,J$2,FORM!$A$2:$A459,">"&$B7+0.5,FORM!$A$2:$A459,"<"&$B7+1.5) -> -800 | K7: =sumifs(FORM!$D$2:$D459,FORM!$C$2:$C459,TODAY!$B$10,FORM!$B$2:$B459,K$2,FORM!$A$2:$A459,">"&$B7+0.5,FORM!$A$2:$A459,"<"&$B7+1.5)-sumifs(FORM!$D$2:$D459,FORM!$C$2:$C459,TODAY!$B$9,FORM!$B$2:$B459,K$2,FORM!$A$2:$A459,">"&$B7+0.5,FORM!$A$2:$A459,"<"&$B7+1.5) -> 0 | ... P7: =sumifs(FORM!$D$2:$D459,FORM!$C$2:$C459,TODAY!$B$10,FORM!$B$2:$B459,P$2,FORM!$A$2:$A459,">"&$B7+0.5,FORM!$A$2:$A459,"<"&$B7+1.5)-sumifs(FORM!$D$2:$D459,FORM!$C$2:$C459,TODAY!$B$9,FORM!$B$2:$B459,P$2,FORM!$A$2:$A459,">"&$B7+0.5,FORM!$A$2:$A459,"<"&$B7+1.5) -> 0 | Q7: 0 | R7: 0 | S7: 0 | T7: 0 | U7: =if(or($C7="",U$2=""),"",(sumifs(FORM!$D$2:$D459,FORM!$C$2:$C459,TODAY!$B$10,FORM!$B$2:$B459,U$2,FORM!$A$2:$A459,">"&$B7+0.5,FORM!$A$2:$A459,"<"&$B7+1.5)-sumifs(FORM!$D$2:$D459,FORM!$C$2:$C459,TODAY!$B$9,FORM!$B$2:$B459,U$2,FORM!$A$2:$A459,">"&$B7+0.5,FORM!$A$2:$A459,"<"&$B7+1.5))/$C7) -> 0
B8: 44846 | C8: 10 | D8: =sumifs(FORM!$D$2:$D459,FORM!$C$2:$C459,TODAY!$B$10,FORM!$B$2:$B459,D$2,FORM!$A$2:$A459,">"&$B8+0.5,FORM!$A$2:$A459,"<"&$B8+1.5)-sumifs(FORM!$D$2:$D459,FORM!$C$2:$C459,TODAY!$B$9,FORM!$B$2:$B459,D$2,FORM!$A$2:$A459,">"&$B8+0.5,FORM!$A$2:$A459,"<"&$B8+1.5) -> 470 | E8: =sumifs(FORM!$D$2:$D459,FORM!$C$2:$C459,TODAY!$B$10,FORM!$B$2:$B459,E$2,FORM!$A$2:$A459,">"&$B8+0.5,FORM!$A$2:$A459,"<"&$B8+1.5)-sumifs(FORM!$D$2:$D459,FORM!$C$2:$C459,TODAY!$B$9,FORM!$B$2:$B459,E$2,FORM!$A$2:$A459,">"&$B8+0.5,FORM!$A$2:$A459,"<"&$B8+1.5) -> -40 | F8: =sumifs(FORM!$D$2:$D459,FORM!$C$2:$C459,TODAY!$B$10,FORM!$B$2:$B459,F$2,FORM!$A$2:$A459,">"&$B8+0.5,FORM!$A$2:$A459,"<"&$B8+1.5)-sumifs(FORM!$D$2:$D459,FORM!$C$2:$C459,TODAY!$B$9,FORM!$B$2:$B459,F$2,FORM!$A$2:$A459,">"&$B8+0.5,FORM!$A$2:$A459,"<"&$B8+1.5) -> 46 | G8: =sumifs(FORM!$D$2:$D459,FORM!$C$2:$C459,TODAY!$B$10,FORM!$B$2:$B459,G$2,FORM!$A$2:$A459,">"&$B8+0.5,FORM!$A$2:$A459,"<"&$B8+1.5)-sumifs(FORM!$D$2:$D459,FORM!$C$2:$C459,TODAY!$B$9,FORM!$B$2:$B459,G$2,FORM!$A$2:$A459,">"&$B8+0.5,FORM!$A$2:$A459,"<"&$B8+1.5) -> 0 | H8: =sumifs(FORM!$D$2:$D459,FORM!$C$2:$C459,TODAY!$B$10,FORM!$B$2:$B459,H$2,FORM!$A$2:$A459,">"&$B8+0.5,FORM!$A$2:$A459,"<"&$B8+1.5)-sumifs(FORM!$D$2:$D459,FORM!$C$2:$C459,TODAY!$B$9,FORM!$B$2:$B459,H$2,FORM!$A$2:$A459,">"&$B8+0.5,FORM!$A$2:$A459,"<"&$B8+1.5) -> 123 | I8: =sumifs(FORM!$D$2:$D459,FORM!$C$2:$C459,TODAY!$B$10,FORM!$B$2:$B459,I$2,FORM!$A$2:$A459,">"&$B8+0.5,FORM!$A$2:$A459,"<"&$B8+1.5)-sumifs(FORM!$D$2:$D459,FORM!$C$2:$C459,TODAY!$B$9,FORM!$B$2:$B459,I$2,FORM!$A$2:$A459,">"&$B8+0.5,FORM!$A$2:$A459,"<"&$B8+1.5) -> -40 | J8: =sumifs(FORM!$D$2:$D459,FORM!$C$2:$C459,TODAY!$B$10,FORM!$B$2:$B459,J$2,FORM!$A$2:$A459,">"&$B8+0.5,FORM!$A$2:$A459,"<"&$B8+1.5)-sumifs(FORM!$D$2:$D459,FORM!$C$2:$C459,TODAY!$B$9,FORM!$B$2:$B459,J$2,FORM!$A$2:$A459,">"&$B8+0.5,FORM!$A$2:$A459,"<"&$B8+1.5) -> -559 | K8: =sumifs(FORM!$D$2:$D459,FORM!$C$2:$C459,TODAY!$B$10,FORM!$B$2:$B459,K$2,FORM!$A$2:$A459,">"&$B8+0.5,FORM!$A$2:$A459,"<"&$B8+1.5)-sumifs(FORM!$D$2:$D459,FORM!$C$2:$C459,TODAY!$B$9,FORM!$B$2:$B459,K$2,FORM!$A$2:$A459,">"&$B8+0.5,FORM!$A$2:$A459,"<"&$B8+1.5) -> 0 | ... P8: =sumifs(FORM!$D$2:$D459,FORM!$C$2:$C459,TODAY!$B$10,FORM!$B$2:$B459,P$2,FORM!$A$2:$A459,">"&$B8+0.5,FORM!$A$2:$A459,"<"&$B8+1.5)-sumifs(FORM!$D$2:$D459,FORM!$C$2:$C459,TODAY!$B$9,FORM!$B$2:$B459,P$2,FORM!$A$2:$A459,">"&$B8+0.5,FORM!$A$2:$A459,"<"&$B8+1.5) -> 0 | Q8: 0 | R8: 0 | S8: 0 | T8: 0 | U8: =if(or($C8="",U$2=""),"",(sumifs(FORM!$D$2:$D459,FORM!$C$2:$C459,TODAY!$B$10,FORM!$B$2:$B459,U$2,FORM!$A$2:$A459,">"&$B8+0.5,FORM!$A$2:$A459,"<"&$B8+1.5)-sumifs(FORM!$D$2:$D459,FORM!$C$2:$C459,TODAY!$B$9,FORM!$B$2:$B459,U$2,FORM!$A$2:$A459,">"&$B8+0.5,FORM!$A$2:$A459,"<"&$B8+1.5))/$C8) -> 0
B9: 44847 | C9: 10 | D9: =sumifs(FORM!$D$2:$D459,FORM!$C$2:$C459,TODAY!$B$10,FORM!$B$2:$B459,D$2,FORM!$A$2:$A459,">"&$B9+0.5,FORM!$A$2:$A459,"<"&$B9+1.5)-sumifs(FORM!$D$2:$D459,FORM!$C$2:$C459,TODAY!$B$9,FORM!$B$2:$B459,D$2,FORM!$A$2:$A459,">"&$B9+0.5,FORM!$A$2:$A459,"<"&$B9+1.5) -> -230 | E9: =sumifs(FORM!$D$2:$D459,FORM!$C$2:$C459,TODAY!$B$10,FORM!$B$2:$B459,E$2,FORM!$A$2:$A459,">"&$B9+0.5,FORM!$A$2:$A459,"<"&$B9+1.5)-sumifs(FORM!$D$2:$D459,FORM!$C$2:$C459,TODAY!$B$9,FORM!$B$2:$B459,E$2,FORM!$A$2:$A459,">"&$B9+0.5,FORM!$A$2:$A459,"<"&$B9+1.5) -> -156 | F9: =sumifs(FORM!$D$2:$D459,FORM!$C$2:$C459,TODAY!$B$10,FORM!$B$2:$B459,F$2,FORM!$A$2:$A459,">"&$B9+0.5,FORM!$A$2:$A459,"<"&$B9+1.5)-sumifs(FORM!$D$2:$D459,FORM!$C$2:$C459,TODAY!$B$9,FORM!$B$2:$B459,F$2,FORM!$A$2:$A459,">"&$B9+0.5,FORM!$A$2:$A459,"<"&$B9+1.5) -> 890 | G9: =sumifs(FORM!$D$2:$D459,FORM!$C$2:$C459,TODAY!$B$10,FORM!$B$2:$B459,G$2,FORM!$A$2:$A459,">"&$B9+0.5,FORM!$A$2:$A459,"<"&$B9+1.5)-sumifs(FORM!$D$2:$D459,FORM!$C$2:$C459,TODAY!$B$9,FORM!$B$2:$B459,G$2,FORM!$A$2:$A459,">"&$B9+0.5,FORM!$A$2:$A459,"<"&$B9+1.5) -> -900 | H9: =sumifs(FORM!$D$2:$D459,FORM!$C$2:$C459,TODAY!$B$10,FORM!$B$2:$B459,H$2,FORM!$A$2:$A459,">"&$B9+0.5,FORM!$A$2:$A459,"<"&$B9+1.5)-sumifs(FORM!$D$2:$D459,FORM!$C$2:$C459,TODAY!$B$9,FORM!$B$2:$B459,H$2,FORM!$A$2:$A459,">"&$B9+0.5,FORM!$A$2:$A459,"<"&$B9+1.5) -> 90 | I9: =sumifs(FORM!$D$2:$D459,FORM!$C$2:$C459,TODAY!$B$10,FORM!$B$2:$B459,I$2,FORM!$A$2:$A459,">"&$B9+0.5,FORM!$A$2:$A459,"<"&$B9+1.5)-sumifs(FORM!$D$2:$D459,FORM!$C$2:$C459,TODAY!$B$9,FORM!$B$2:$B459,I$2,FORM!$A$2:$A459,">"&$B9+0.5,FORM!$A$2:$A459,"<"&$B9+1.5) -> -279 | J9: =sumifs(FORM!$D$2:$D459,FORM!$C$2:$C459,TODAY!$B$10,FORM!$B$2:$B459,J$2,FORM!$A$2:$A459,">"&$B9+0.5,FORM!$A$2:$A459,"<"&$B9+1.5)-sumifs(FORM!$D$2:$D459,FORM!$C$2:$C459,TODAY!$B$9,FORM!$B$2:$B459,J$2,FORM!$A$2:$A459,">"&$B9+0.5,FORM!$A$2:$A459,"<"&$B9+1.5) -> 585 | K9: =sumifs(FORM!$D$2:$D459,FORM!$C$2:$C459,TODAY!$B$10,FORM!$B$2:$B459,K$2,FORM!$A$2:$A459,">"&$B9+0.5,FORM!$A$2:$A459,"<"&$B9+1.5)-sumifs(FORM!$D$2:$D459,FORM!$C$2:$C459,TODAY!$B$9,FORM!$B$2:$B459,K$2,FORM!$A$2:$A459,">"&$B9+0.5,FORM!$A$2:$A459,"<"&$B9+1.5) -> 0 | ... P9: =sumifs(FORM!$D$2:$D459,FORM!$C$2:$C459,TODAY!$B$10,FORM!$B$2:$B459,P$2,FORM!$A$2:$A459,">"&$B9+0.5,FORM!$A$2:$A459,"<"&$B9+1.5)-sumifs(FORM!$D$2:$D459,FORM!$C$2:$C459,TODAY!$B$9,FORM!$B$2:$B459,P$2,FORM!$A$2:$A459,">"&$B9+0.5,FORM!$A$2:$A459,"<"&$B9+1.5) -> 0 | Q9: 0 | R9: 0 | S9: 0 | T9: 0 | U9: =if(or($C9="",U$2=""),"",(sumifs(FORM!$D$2:$D459,FORM!$C$2:$C459,TODAY!$B$10,FORM!$B$2:$B459,U$2,FORM!$A$2:$A459,">"&$B9+0.5,FORM!$A$2:$A459,"<"&$B9+1.5)-sumifs(FORM!$D$2:$D459,FORM!$C$2:$C459,TODAY!$B$9,FORM!$B$2:$B459,U$2,FORM!$A$2:$A459,">"&$B9+0.5,FORM!$A$2:$A459,"<"&$B9+1.5))/$C9) -> 0
B10: 44849 | C10: 10 | D10: =sumifs(FORM!$D$2:$D459,FORM!$C$2:$C459,TODAY!$B$10,FORM!$B$2:$B459,D$2,FORM!$A$2:$A459,">"&$B10+0.5,FORM!$A$2:$A459,"<"&$B10+1.5)-sumifs(FORM!$D$2:$D459,FORM!$C$2:$C459,TODAY!$B$9,FORM!$B$2:$B459,D$2,FORM!$A$2:$A459,">"&$B10+0.5,FORM!$A$2:$A459,"<"&$B10+1.5) -> -800 | E10: =sumifs(FORM!$D$2:$D459,FORM!$C$2:$C459,TODAY!$B$10,FORM!$B$2:$B459,E$2,FORM!$A$2:$A459,">"&$B10+0.5,FORM!$A$2:$A459,"<"&$B10+1.5)-sumifs(FORM!$D$2:$D459,FORM!$C$2:$C459,TODAY!$B$9,FORM!$B$2:$B459,E$2,FORM!$A$2:$A459,">"&$B10+0.5,FORM!$A$2:$A459,"<"&$B10+1.5) -> 647 | F10: =sumifs(FORM!$D$2:$D459,FORM!$C$2:$C459,TODAY!$B$10,FORM!$B$2:$B459,F$2,FORM!$A$2:$A459,">"&$B10+0.5,FORM!$A$2:$A459,"<"&$B10+1.5)-sumifs(FORM!$D$2:$D459,FORM!$C$2:$C459,TODAY!$B$9,FORM!$B$2:$B459,F$2,FORM!$A$2:$A459,">"&$B10+0.5,FORM!$A$2:$A459,"<"&$B10+1.5) -> -47 | G10: =sumifs(FORM!$D$2:$D459,FORM!$C$2:$C459,TODAY!$B$10,FORM!$B$2:$B459,G$2,FORM!$A$2:$A459,">"&$B10+0.5,FORM!$A$2:$A459,"<"&$B10+1.5)-sumifs(FORM!$D$2:$D459,FORM!$C$2:$C459,TODAY!$B$9,FORM!$B$2:$B459,G$2,FORM!$A$2:$A459,">"&$B10+0.5,FORM!$A$2:$A459,"<"&$B10+1.5) -> 0 | H10: =sumifs(FORM!$D$2:$D459,FORM!$C$2:$C459,TODAY!$B$10,FORM!$B$2:$B459,H$2,FORM!$A$2:$A459,">"&$B10+0.5,FORM!$A$2:$A459,"<"&$B10+1.5)-sumifs(FORM!$D$2:$D459,FORM!$C$2:$C459,TODAY!$B$9,FORM!$B$2:$B459,H$2,FORM!$A$2:$A459,">"&$B10+0.5,FORM!$A$2:$A459,"<"&$B10+1.5) -> -139 | I10: =sumifs(FORM!$D$2:$D459,FORM!$C$2:$C459,TODAY!$B$10,FORM!$B$2:$B459,I$2,FORM!$A$2:$A459,">"&$B10+0.5,FORM!$A$2:$A459,"<"&$B10+1.5)-sumifs(FORM!$D$2:$D459,FORM!$C$2:$C459,TODAY!$B$9,FORM!$B$2:$B459,I$2,FORM!$A$2:$A459,">"&$B10+0.5,FORM!$A$2:$A459,"<"&$B10+1.5) -> 616 | J10: =sumifs(FORM!$D$2:$D459,FORM!$C$2:$C459,TODAY!$B$10,FORM!$B$2:$B459,J$2,FORM!$A$2:$A459,">"&$B10+0.5,FORM!$A$2:$A459,"<"&$B10+1.5)-sumifs(FORM!$D$2:$D459,FORM!$C$2:$C459,TODAY!$B$9,FORM!$B$2:$B459,J$2,FORM!$A$2:$A459,">"&$B10+0.5,FORM!$A$2:$A459,"<"&$B10+1.5) -> -57 | K10: =sumifs(FORM!$D$2:$D459,FORM!$C$2:$C459,TODAY!$B$10,FORM!$B$2:$B459,K$2,FORM!$A$2:$A459,">"&$B10+0.5,FORM!$A$2:$A459,"<"&$B10+1.5)-sumifs(FORM!$D$2:$D459,FORM!$C$2:$C459,TODAY!$B$9,FORM!$B$2:$B459,K$2,FORM!$A$2:$A459,">"&$B10+0.5,FORM!$A$2:$A459,"<"&$B10+1.5) -> -200 | ... P10: =sumifs(FORM!$D$2:$D459,FORM!$C$2:$C459,TODAY!$B$10,FORM!$B$2:$B459,P$2,FORM!$A$2:$A459,">"&$B10+0.5,FORM!$A$2:$A459,"<"&$B10+1.5)-sumifs(FORM!$D$2:$D459,FORM!$C$2:$C459,TODAY!$B$9,FORM!$B$2:$B459,P$2,FORM!$A$2:$A459,">"&$B10+0.5,FORM!$A$2:$A459,"<"&$B10+1.5) -> 0 | Q10: 0 | R10: 0 | S10: 0 | T10: 0 | U10: =if(or($C10="",U$2=""),"",(sumifs(FORM!$D$2:$D459,FORM!$C$2:$C459,TODAY!$B$10,FORM!$B$2:$B459,U$2,FORM!$A$2:$A459,">"&$B10+0.5,FORM!$A$2:$A459,"<"&$B10+1.5)-sumifs(FORM!$D$2:$D459,FORM!$C$2:$C459,TODAY!$B$9,FORM!$B$2:$B459,U$2,FORM!$A$2:$A459,">"&$B10+0.5,FORM!$A$2:$A459,"<"&$B10+1.5))/$C10) -> 0
B11: 44857 | C11: 10 | D11: =sumifs(FORM!$D$2:$D459,FORM!$C$2:$C459,TODAY!$B$10,FORM!$B$2:$B459,D$2,FORM!$A$2:$A459,">"&$B11+0.5,FORM!$A$2:$A459,"<"&$B11+1.5)-sumifs(FORM!$D$2:$D459,FORM!$C$2:$C459,TODAY!$B$9,FORM!$B$2:$B459,D$2,FORM!$A$2:$A459,">"&$B11+0.5,FORM!$A$2:$A459,"<"&$B11+1.5) -> 530 | E11: =sumifs(FORM!$D$2:$D459,FORM!$C$2:$C459,TODAY!$B$10,FORM!$B$2:$B459,E$2,FORM!$A$2:$A459,">"&$B11+0.5,FORM!$A$2:$A459,"<"&$B11+1.5)-sumifs(FORM!$D$2:$D459,FORM!$C$2:$C459,TODAY!$B$9,FORM!$B$2:$B459,E$2,FORM!$A$2:$A459,">"&$B11+0.5,FORM!$A$2:$A459,"<"&$B11+1.5) -> 135 | F11: =sumifs(FORM!$D$2:$D459,FORM!$C$2:$C459,TODAY!$B$10,FORM!$B$2:$B459,F$2,FORM!$A$2:$A459,">"&$B11+0.5,FORM!$A$2:$A459,"<"&$B11+1.5)-sumifs(FORM!$D$2:$D459,FORM!$C$2:$C459,TODAY!$B$9,FORM!$B$2:$B459,F$2,FORM!$A$2:$A459,">"&$B11+0.5,FORM!$A$2:$A459,"<"&$B11+1.5) -> 578 | G11: =sumifs(FORM!$D$2:$D459,FORM!$C$2:$C459,TODAY!$B$10,FORM!$B$2:$B459,G$2,FORM!$A$2:$A459,">"&$B11+0.5,FORM!$A$2:$A459,"<"&$B11+1.5)-sumifs(FORM!$D$2:$D459,FORM!$C$2:$C459,TODAY!$B$9,FORM!$B$2:$B459,G$2,FORM!$A$2:$A459,">"&$B11+0.5,FORM!$A$2:$A459,"<"&$B11+1.5) -> -1023 | H11: =sumifs(FORM!$D$2:$D459,FORM!$C$2:$C459,TODAY!$B$10,FORM!$B$2:$B459,H$2,FORM!$A$2:$A459,">"&$B11+0.5,FORM!$A$2:$A459,"<"&$B11+1.5)-sumifs(FORM!$D$2:$D459,FORM!$C$2:$C459,TODAY!$B$9,FORM!$B$2:$B459,H$2,FORM!$A$2:$A459,">"&$B11+0.5,FORM!$A$2:$A459,"<"&$B11+1.5) -> -40 | I11: =sumifs(FORM!$D$2:$D459,FORM!$C$2:$C459,TODAY!$B$10,FORM!$B$2:$B459,I$2,FORM!$A$2:$A459,">"&$B11+0.5,FORM!$A$2:$A459,"<"&$B11+1.5)-sumifs(FORM!$D$2:$D459,FORM!$C$2:$C459,TODAY!$B$9,FORM!$B$2:$B459,I$2,FORM!$A$2:$A459,">"&$B11+0.5,FORM!$A$2:$A459,"<"&$B11+1.5) -> 0 | J11: =sumifs(FORM!$D$2:$D459,FORM!$C$2:$C459,TODAY!$B$10,FORM!$B$2:$B459,J$2,FORM!$A$2:$A459,">"&$B11+0.5,FORM!$A$2:$A459,"<"&$B11+1.5)-sumifs(FORM!$D$2:$D459,FORM!$C$2:$C459,TODAY!$B$9,FORM!$B$2:$B459,J$2,FORM!$A$2:$A459,">"&$B11+0.5,FORM!$A$2:$A459,"<"&$B11+1.5) -> -180 | K11: =sumifs(FORM!$D$2:$D459,FORM!$C$2:$C459,TODAY!$B$10,FORM!$B$2:$B459,K$2,FORM!$A$2:$A459,">"&$B11+0.5,FORM!$A$2:$A459,"<"&$B11+1.5)-sumifs(FORM!$D$2:$D459,FORM!$C$2:$C459,TODAY!$B$9,FORM!$B$2:$B459,K$2,FORM!$A$2:$A459,">"&$B11+0.5,FORM!$A$2:$A459,"<"&$B11+1.5) -> 0 | ... P11: =sumifs(FORM!$D$2:$D459,FORM!$C$2:$C459,TODAY!$B$10,FORM!$B$2:$B459,P$2,FORM!$A$2:$A459,">"&$B11+0.5,FORM!$A$2:$A459,"<"&$B11+1.5)-sumifs(FORM!$D$2:$D459,FORM!$C$2:$C459,TODAY!$B$9,FORM!$B$2:$B459,P$2,FORM!$A$2:$A459,">"&$B11+0.5,FORM!$A$2:$A459,"<"&$B11+1.5) -> 0 | Q11: 0 | R11: 0 | S11: 0 | T11: 0 | U11: =if(or($C11="",U$2=""),"",(sumifs(FORM!$D$2:$D459,FORM!$C$2:$C459,TODAY!$B$10,FORM!$B$2:$B459,U$2,FORM!$A$2:$A459,">"&$B11+0.5,FORM!$A$2:$A459,"<"&$B11+1.5)-sumifs(FORM!$D$2:$D459,FORM!$C$2:$C459,TODAY!$B$9,FORM!$B$2:$B459,U$2,FORM!$A$2:$A459,">"&$B11+0.5,FORM!$A$2:$A459,"<"&$B11+1.5))/$C11) -> 0
B12: 44863 | C12: 10 | D12: =sumifs(FORM!$D$2:$D459,FORM!$C$2:$C459,TODAY!$B$10,FORM!$B$2:$B459,D$2,FORM!$A$2:$A459,">"&$B12+0.5,FORM!$A$2:$A459,"<"&$B12+1.5)-sumifs(FORM!$D$2:$D459,FORM!$C$2:$C459,TODAY!$B$9,FORM!$B$2:$B459,D$2,FORM!$A$2:$A459,">"&$B12+0.5,FORM!$A$2:$A459,"<"&$B12+1.5) -> 450 | E12: =sumifs(FORM!$D$2:$D459,FORM!$C$2:$C459,TODAY!$B$10,FORM!$B$2:$B459,E$2,FORM!$A$2:$A459,">"&$B12+0.5,FORM!$A$2:$A459,"<"&$B12+1.5)-sumifs(FORM!$D$2:$D459,FORM!$C$2:$C459,TODAY!$B$9,FORM!$B$2:$B459,E$2,FORM!$A$2:$A459,">"&$B12+0.5,FORM!$A$2:$A459,"<"&$B12+1.5) -> 90 | F12: =sumifs(FORM!$D$2:$D459,FORM!$C$2:$C459,TODAY!$B$10,FORM!$B$2:$B459,F$2,FORM!$A$2:$A459,">"&$B12+0.5,FORM!$A$2:$A459,"<"&$B12+1.5)-sumifs(FORM!$D$2:$D459,FORM!$C$2:$C459,TODAY!$B$9,FORM!$B$2:$B459,F$2,FORM!$A$2:$A459,">"&$B12+0.5,FORM!$A$2:$A459,"<"&$B12+1.5) -> -27 | G12: =sumifs(FORM!$D$2:$D459,FORM!$C$2:$C459,TODAY!$B$10,FORM!$B$2:$B459,G$2,FORM!$A$2:$A459,">"&$B12+0.5,FORM!$A$2:$A459,"<"&$B12+1.5)-sumifs(FORM!$D$2:$D459,FORM!$C$2:$C459,TODAY!$B$9,FORM!$B$2:$B459,G$2,FORM!$A$2:$A459,">"&$B12+0.5,FORM!$A$2:$A459,"<"&$B12+1.5) -> -464 | H12: =sumifs(FORM!$D$2:$D459,FORM!$C$2:$C459,TODAY!$B$10,FORM!$B$2:$B459,H$2,FORM!$A$2:$A459,">"&$B12+0.5,FORM!$A$2:$A459,"<"&$B12+1.5)-sumifs(FORM!$D$2:$D459,FORM!$C$2:$C459,TODAY!$B$9,FORM!$B$2:$B459,H$2,FORM!$A$2:$A459,">"&$B12+0.5,FORM!$A$2:$A459,"<"&$B12+1.5) -> -49 | I12: =sumifs(FORM!$D$2:$D459,FORM!$C$2:$C459,TODAY!$B$10,FORM!$B$2:$B459,I$2,FORM!$A$2:$A459,">"&$B12+0.5,FORM!$A$2:$A459,"<"&$B12+1.5)-sumifs(FORM!$D$2:$D459,FORM!$C$2:$C459,TODAY!$B$9,FORM!$B$2:$B459,I$2,FORM!$A$2:$A459,">"&$B12+0.5,FORM!$A$2:$A459,"<"&$B12+1.5) -> 0 | J12: =sumifs(FORM!$D$2:$D459,FORM!$C$2:$C459,TODAY!$B$10,FORM!$B$2:$B459,J$2,FORM!$A$2:$A459,">"&$B12+0.5,FORM!$A$2:$A459,"<"&$B12+1.5)-sumifs(FORM!$D$2:$D459,FORM!$C$2:$C459,TODAY!$B$9,FORM!$B$2:$B459,J$2,FORM!$A$2:$A459,">"&$B12+0.5,FORM!$A$2:$A459,"<"&$B12+1.5) -> 0 | K12: =sumifs(FORM!$D$2:$D459,FORM!$C$2:$C459,TODAY!$B$10,FORM!$B$2:$B459,K$2,FORM!$A$2:$A459,">"&$B12+0.5,FORM!$A$2:$A459,"<"&$B12+1.5)-sumifs(FORM!$D$2:$D459,FORM!$C$2:$C459,TODAY!$B$9,FORM!$B$2:$B459,K$2,FORM!$A$2:$A459,">"&$B12+0.5,FORM!$A$2:$A459,"<"&$B12+1.5) -> 0 | ... P12: =sumifs(FORM!$D$2:$D459,FORM!$C$2:$C459,TODAY!$B$10,FORM!$B$2:$B459,P$2,FORM!$A$2:$A459,">"&$B12+0.5,FORM!$A$2:$A459,"<"&$B12+1.5)-sumifs(FORM!$D$2:$D459,FORM!$C$2:$C459,TODAY!$B$9,FORM!$B$2:$B459,P$2,FORM!$A$2:$A459,">"&$B12+0.5,FORM!$A$2:$A459,"<"&$B12+1.5) -> 0 | Q12: 0 | R12: 0 | S12: 0 | T12: 0 | U12: =if(or($C12="",U$2=""),"",(sumifs(FORM!$D$2:$D459,FORM!$C$2:$C459,TODAY!$B$10,FORM!$B$2:$B459,U$2,FORM!$A$2:$A459,">"&$B12+0.5,FORM!$A$2:$A459,"<"&$B12+1.5)-sumifs(FORM!$D$2:$D459,FORM!$C$2:$C459,TODAY!$B$9,FORM!$B$2:$B459,U$2,FORM!$A$2:$A459,">"&$B12+0.5,FORM!$A$2:$A459,"<"&$B12+1.5))/$C12) -> 0
B13: 44898 | C13: 1 | D13: =sumifs(FORM!$D$2:$D459,FORM!$C$2:$C459,TODAY!$B$10,FORM!$B$2:$B459,D$2,FORM!$A$2:$A459,">"&$B13+0.5,FORM!$A$2:$A459,"<"&$B13+1.5)-sumifs(FORM!$D$2:$D459,FORM!$C$2:$C459,TODAY!$B$9,FORM!$B$2:$B459,D$2,FORM!$A$2:$A459,">"&$B13+0.5,FORM!$A$2:$A459,"<"&$B13+1.5) -> 1940 | E13: =sumifs(FORM!$D$2:$D459,FORM!$C$2:$C459,TODAY!$B$10,FORM!$B$2:$B459,E$2,FORM!$A$2:$A459,">"&$B13+0.5,FORM!$A$2:$A459,"<"&$B13+1.5)-sumifs(FORM!$D$2:$D459,FORM!$C$2:$C459,TODAY!$B$9,FORM!$B$2:$B459,E$2,FORM!$A$2:$A459,">"&$B13+0.5,FORM!$A$2:$A459,"<"&$B13+1.5) -> 0 | F13: =sumifs(FORM!$D$2:$D459,FORM!$C$2:$C459,TODAY!$B$10,FORM!$B$2:$B459,F$2,FORM!$A$2:$A459,">"&$B13+0.5,FORM!$A$2:$A459,"<"&$B13+1.5)-sumifs(FORM!$D$2:$D459,FORM!$C$2:$C459,TODAY!$B$9,FORM!$B$2:$B459,F$2,FORM!$A$2:$A459,">"&$B13+0.5,FORM!$A$2:$A459,"<"&$B13+1.5) -> 200 | G13: =sumifs(FORM!$D$2:$D459,FORM!$C$2:$C459,TODAY!$B$10,FORM!$B$2:$B459,G$2,FORM!$A$2:$A459,">"&$B13+0.5,FORM!$A$2:$A459,"<"&$B13+1.5)-sumifs(FORM!$D$2:$D459,FORM!$C$2:$C459,TODAY!$B$9,FORM!$B$2:$B459,G$2,FORM!$A$2:$A459,">"&$B13+0.5,FORM!$A$2:$A459,"<"&$B13+1.5) -> 0 | H13: =sumifs(FORM!$D$2:$D459,FORM!$C$2:$C459,TODAY!$B$10,FORM!$B$2:$B459,H$2,FORM!$A$2:$A459,">"&$B13+0.5,FORM!$A$2:$A459,"<"&$B13+1.5)-sumifs(FORM!$D$2:$D459,FORM!$C$2:$C459,TODAY!$B$9,FORM!$B$2:$B459,H$2,FORM!$A$2:$A459,">"&$B13+0.5,FORM!$A$2:$A459,"<"&$B13+1.5) -> -1910 | I13: =sumifs(FORM!$D$2:$D459,FORM!$C$2:$C459,TODAY!$B$10,FORM!$B$2:$B459,I$2,FORM!$A$2:$A459,">"&$B13+0.5,FORM!$A$2:$A459,"<"&$B13+1.5)-sumifs(FORM!$D$2:$D459,FORM!$C$2:$C459,TODAY!$B$9,FORM!$B$2:$B459,I$2,FORM!$A$2:$A459,">"&$B13+0.5,FORM!$A$2:$A459,"<"&$B13+1.5) -> -20 | J13: =sumifs(FORM!$D$2:$D459,FORM!$C$2:$C459,TODAY!$B$10,FORM!$B$2:$B459,J$2,FORM!$A$2:$A459,">"&$B13+0.5,FORM!$A$2:$A459,"<"&$B13+1.5)-sumifs(FORM!$D$2:$D459,FORM!$C$2:$C459,TODAY!$B$9,FORM!$B$2:$B459,J$2,FORM!$A$2:$A459,">"&$B13+0.5,FORM!$A$2:$A459,"<"&$B13+1.5) -> 1000 | K13: =sumifs(FORM!$D$2:$D459,FORM!$C$2:$C459,TODAY!$B$10,FORM!$B$2:$B459,K$2,FORM!$A$2:$A459,">"&$B13+0.5,FORM!$A$2:$A459,"<"&$B13+1.5)-sumifs(FORM!$D$2:$D459,FORM!$C$2:$C459,TODAY!$B$9,FORM!$B$2:$B459,K$2,FORM!$A$2:$A459,">"&$B13+0.5,FORM!$A$2:$A459,"<"&$B13+1.5) -> 0 | ... P13: =sumifs(FORM!$D$2:$D459,FORM!$C$2:$C459,TODAY!$B$10,FORM!$B$2:$B459,P$2,FORM!$A$2:$A459,">"&$B13+0.5,FORM!$A$2:$A459,"<"&$B13+1.5)-sumifs(FORM!$D$2:$D459,FORM!$C$2:$C459,TODAY!$B$9,FORM!$B$2:$B459,P$2,FORM!$A$2:$A459,">"&$B13+0.5,FORM!$A$2:$A459,"<"&$B13+1.5) -> 0 | Q13: 0 | R13: 0 | S13: 0 | T13: 0 | U13: =if(or($C13="",U$2=""),"",(sumifs(FORM!$D$2:$D459,FORM!$C$2:$C459,TODAY!$B$10,FORM!$B$2:$B459,U$2,FORM!$A$2:$A459,">"&$B13+0.5,FORM!$A$2:$A459,"<"&$B13+1.5)-sumifs(FORM!$D$2:$D459,FORM!$C$2:$C459,TODAY!$B$9,FORM!$B$2:$B459,U$2,FORM!$A$2:$A459,">"&$B13+0.5,FORM!$A$2:$A459,"<"&$B13+1.5))/$C13) -> 0
B14: 44919 | C14: 10 | D14: =sumifs(FORM!$D$2:$D459,FORM!$C$2:$C459,TODAY!$B$10,FORM!$B$2:$B459,D$2,FORM!$A$2:$A459,">"&$B14+0.5,FORM!$A$2:$A459,"<"&$B14+1.5)-sumifs(FORM!$D$2:$D459,FORM!$C$2:$C459,TODAY!$B$9,FORM!$B$2:$B459,D$2,FORM!$A$2:$A459,">"&$B14+0.5,FORM!$A$2:$A459,"<"&$B14+1.5) -> 485 | E14: =sumifs(FORM!$D$2:$D459,FORM!$C$2:$C459,TODAY!$B$10,FORM!$B$2:$B459,E$2,FORM!$A$2:$A459,">"&$B14+0.5,FORM!$A$2:$A459,"<"&$B14+1.5)-sumifs(FORM!$D$2:$D459,FORM!$C$2:$C459,TODAY!$B$9,FORM!$B$2:$B459,E$2,FORM!$A$2:$A459,">"&$B14+0.5,FORM!$A$2:$A459,"<"&$B14+1.5) -> 480 | F14: =sumifs(FORM!$D$2:$D459,FORM!$C$2:$C459,TODAY!$B$10,FORM!$B$2:$B459,F$2,FORM!$A$2:$A459,">"&$B14+0.5,FORM!$A$2:$A459,"<"&$B14+1.5)-sumifs(FORM!$D$2:$D459,FORM!$C$2:$C459,TODAY!$B$9,FORM!$B$2:$B459,F$2,FORM!$A$2:$A459,">"&$B14+0.5,FORM!$A$2:$A459,"<"&$B14+1.5) -> -409 | G14: =sumifs(FORM!$D$2:$D459,FORM!$C$2:$C459,TODAY!$B$10,FORM!$B$2:$B459,G$2,FORM!$A$2:$A459,">"&$B14+0.5,FORM!$A$2:$A459,"<"&$B14+1.5)-sumifs(FORM!$D$2:$D459,FORM!$C$2:$C459,TODAY!$B$9,FORM!$B$2:$B459,G$2,FORM!$A$2:$A459,">"&$B14+0.5,FORM!$A$2:$A459,"<"&$B14+1.5) -> -19 | H14: =sumifs(FORM!$D$2:$D459,FORM!$C$2:$C459,TODAY!$B$10,FORM!$B$2:$B459,H$2,FORM!$A$2:$A459,">"&$B14+0.5,FORM!$A$2:$A459,"<"&$B14+1.5)-sumifs(FORM!$D$2:$D459,FORM!$C$2:$C459,TODAY!$B$9,FORM!$B$2:$B459,H$2,FORM!$A$2:$A459,">"&$B14+0.5,FORM!$A$2:$A459,"<"&$B14+1.5) -> -480 | I14: =sumifs(FORM!$D$2:$D459,FORM!$C$2:$C459,TODAY!$B$10,FORM!$B$2:$B459,I$2,FORM!$A$2:$A459,">"&$B14+0.5,FORM!$A$2:$A459,"<"&$B14+1.5)-sumifs(FORM!$D$2:$D459,FORM!$C$2:$C459,TODAY!$B$9,FORM!$B$2:$B459,I$2,FORM!$A$2:$A459,">"&$B14+0.5,FORM!$A$2:$A459,"<"&$B14+1.5) -> 709 | J14: =sumifs(FORM!$D$2:$D459,FORM!$C$2:$C459,TODAY!$B$10,FORM!$B$2:$B459,J$2,FORM!$A$2:$A459,">"&$B14+0.5,FORM!$A$2:$A459,"<"&$B14+1.5)-sumifs(FORM!$D$2:$D459,FORM!$C$2:$C459,TODAY!$B$9,FORM!$B$2:$B459,J$2,FORM!$A$2:$A459,">"&$B14+0.5,FORM!$A$2:$A459,"<"&$B14+1.5) -> -766 | K14: =sumifs(FORM!$D$2:$D459,FORM!$C$2:$C459,TODAY!$B$10,FORM!$B$2:$B459,K$2,FORM!$A$2:$A459,">"&$B14+0.5,FORM!$A$2:$A459,"<"&$B14+1.5)-sumifs(FORM!$D$2:$D459,FORM!$C$2:$C459,TODAY!$B$9,FORM!$B$2:$B459,K$2,FORM!$A$2:$A459,">"&$B14+0.5,FORM!$A$2:$A459,"<"&$B14+1.5) -> 0 | ... P14: =sumifs(FORM!$D$2:$D459,FORM!$C$2:$C459,TODAY!$B$10,FORM!$B$2:$B459,P$2,FORM!$A$2:$A459,">"&$B14+0.5,FORM!$A$2:$A459,"<"&$B14+1.5)-sumifs(FORM!$D$2:$D459,FORM!$C$2:$C459,TODAY!$B$9,FORM!$B$2:$B459,P$2,FORM!$A$2:$A459,">"&$B14+0.5,FORM!$A$2:$A459,"<"&$B14+1.5) -> 0 | Q14: 0 | R14: 0 | S14: 0 | T14: 0 | U14: =if(or($C14="",U$2=""),"",(sumifs(FORM!$D$2:$D459,FORM!$C$2:$C459,TODAY!$B$10,FORM!$B$2:$B459,U$2,FORM!$A$2:$A459,">"&$B14+0.5,FORM!$A$2:$A459,"<"&$B14+1.5)-sumifs(FORM!$D$2:$D459,FORM!$C$2:$C459,TODAY!$B$9,FORM!$B$2:$B459,U$2,FORM!$A$2:$A459,">"&$B14+0.5,FORM!$A$2:$A459,"<"&$B14+1.5))/$C14) -> 0
B15: 44926 | C15: 10 | D15: =sumifs(FORM!$D$2:$D459,FORM!$C$2:$C459,TODAY!$B$10,FORM!$B$2:$B459,D$2,FORM!$A$2:$A459,">"&$B15+0.5,FORM!$A$2:$A459,"<"&$B15+1.5)-sumifs(FORM!$D$2:$D459,FORM!$C$2:$C459,TODAY!$B$9,FORM!$B$2:$B459,D$2,FORM!$A$2:$A459,">"&$B15+0.5,FORM!$A$2:$A459,"<"&$B15+1.5) -> 520 | E15: =sumifs(FORM!$D$2:$D459,FORM!$C$2:$C459,TODAY!$B$10,FORM!$B$2:$B459,E$2,FORM!$A$2:$A459,">"&$B15+0.5,FORM!$A$2:$A459,"<"&$B15+1.5)-sumifs(FORM!$D$2:$D459,FORM!$C$2:$C459,TODAY!$B$9,FORM!$B$2:$B459,E$2,FORM!$A$2:$A459,">"&$B15+0.5,FORM!$A$2:$A459,"<"&$B15+1.5) -> -238 | F15: =sumifs(FORM!$D$2:$D459,FORM!$C$2:$C459,TODAY!$B$10,FORM!$B$2:$B459,F$2,FORM!$A$2:$A459,">"&$B15+0.5,FORM!$A$2:$A459,"<"&$B15+1.5)-sumifs(FORM!$D$2:$D459,FORM!$C$2:$C459,TODAY!$B$9,FORM!$B$2:$B459,F$2,FORM!$A$2:$A459,">"&$B15+0.5,FORM!$A$2:$A459,"<"&$B15+1.5) -> -24 | G15: =sumifs(FORM!$D$2:$D459,FORM!$C$2:$C459,TODAY!$B$10,FORM!$B$2:$B459,G$2,FORM!$A$2:$A459,">"&$B15+0.5,FORM!$A$2:$A459,"<"&$B15+1.5)-sumifs(FORM!$D$2:$D459,FORM!$C$2:$C459,TODAY!$B$9,FORM!$B$2:$B459,G$2,FORM!$A$2:$A459,">"&$B15+0.5,FORM!$A$2:$A459,"<"&$B15+1.5) -> 0 | H15: =sumifs(FORM!$D$2:$D459,FORM!$C$2:$C459,TODAY!$B$10,FORM!$B$2:$B459,H$2,FORM!$A$2:$A459,">"&$B15+0.5,FORM!$A$2:$A459,"<"&$B15+1.5)-sumifs(FORM!$D$2:$D459,FORM!$C$2:$C459,TODAY!$B$9,FORM!$B$2:$B459,H$2,FORM!$A$2:$A459,">"&$B15+0.5,FORM!$A$2:$A459,"<"&$B15+1.5) -> 13 | I15: =sumifs(FORM!$D$2:$D459,FORM!$C$2:$C459,TODAY!$B$10,FORM!$B$2:$B459,I$2,FORM!$A$2:$A459,">"&$B15+0.5,FORM!$A$2:$A459,"<"&$B15+1.5)-sumifs(FORM!$D$2:$D459,FORM!$C$2:$C459,TODAY!$B$9,FORM!$B$2:$B459,I$2,FORM!$A$2:$A459,">"&$B15+0.5,FORM!$A$2:$A459,"<"&$B15+1.5) -> -271 | J15: =sumifs(FORM!$D$2:$D459,FORM!$C$2:$C459,TODAY!$B$10,FORM!$B$2:$B459,J$2,FORM!$A$2:$A459,">"&$B15+0.5,FORM!$A$2:$A459,"<"&$B15+1.5)-sumifs(FORM!$D$2:$D459,FORM!$C$2:$C459,TODAY!$B$9,FORM!$B$2:$B459,J$2,FORM!$A$2:$A459,">"&$B15+0.5,FORM!$A$2:$A459,"<"&$B15+1.5) -> 0 | K15: =sumifs(FORM!$D$2:$D459,FORM!$C$2:$C459,TODAY!$B$10,FORM!$B$2:$B459,K$2,FORM!$A$2:$A459,">"&$B15+0.5,FORM!$A$2:$A459,"<"&$B15+1.5)-sumifs(FORM!$D$2:$D459,FORM!$C$2:$C459,TODAY!$B$9,FORM!$B$2:$B459,K$2,FORM!$A$2:$A459,">"&$B15+0.5,FORM!$A$2:$A459,"<"&$B15+1.5) -> 0 | ... P15: =sumifs(FORM!$D$2:$D459,FORM!$C$2:$C459,TODAY!$B$10,FORM!$B$2:$B459,P$2,FORM!$A$2:$A459,">"&$B15+0.5,FORM!$A$2:$A459,"<"&$B15+1.5)-sumifs(FORM!$D$2:$D459,FORM!$C$2:$C459,TODAY!$B$9,FORM!$B$2:$B459,P$2,FORM!$A$2:$A459,">"&$B15+0.5,FORM!$A$2:$A459,"<"&$B15+1.5) -> 0 | Q15: 0 | R15: 0 | S15: 0 | T15: 0 | U15: =if(or($C15="",U$2=""),"",(sumifs(FORM!$D$2:$D459,FORM!$C$2:$C459,TODAY!$B$10,FORM!$B$2:$B459,U$2,FORM!$A$2:$A459,">"&$B15+0.5,FORM!$A$2:$A459,"<"&$B15+1.5)-sumifs(FORM!$D$2:$D459,FORM!$C$2:$C459,TODAY!$B$9,FORM!$B$2:$B459,U$2,FORM!$A$2:$A459,">"&$B15+0.5,FORM!$A$2:$A459,"<"&$B15+1.5))/$C15) -> 0
B16: 44927 | C16: 10 | D16: =sumifs(FORM!$D$2:$D459,FORM!$C$2:$C459,TODAY!$B$10,FORM!$B$2:$B459,D$2,FORM!$A$2:$A459,">"&$B16+0.5,FORM!$A$2:$A459,"<"&$B16+1.5)-sumifs(FORM!$D$2:$D459,FORM!$C$2:$C459,TODAY!$B$9,FORM!$B$2:$B459,D$2,FORM!$A$2:$A459,">"&$B16+0.5,FORM!$A$2:$A459,"<"&$B16+1.5) -> -182 | E16: =sumifs(FORM!$D$2:$D459,FORM!$C$2:$C459,TODAY!$B$10,FORM!$B$2:$B459,E$2,FORM!$A$2:$A459,">"&$B16+0.5,FORM!$A$2:$A459,"<"&$B16+1.5)-sumifs(FORM!$D$2:$D459,FORM!$C$2:$C459,TODAY!$B$9,FORM!$B$2:$B459,E$2,FORM!$A$2:$A459,">"&$B16+0.5,FORM!$A$2:$A459,"<"&$B16+1.5) -> 241 | F16: =sumifs(FORM!$D$2:$D459,FORM!$C$2:$C459,TODAY!$B$10,FORM!$B$2:$B459,F$2,FORM!$A$2:$A459,">"&$B16+0.5,FORM!$A$2:$A459,"<"&$B16+1.5)-sumifs(FORM!$D$2:$D459,FORM!$C$2:$C459,TODAY!$B$9,FORM!$B$2:$B459,F$2,FORM!$A$2:$A459,">"&$B16+0.5,FORM!$A$2:$A459,"<"&$B16+1.5) -> 651 | G16: =sumifs(FORM!$D$2:$D459,FORM!$C$2:$C459,TODAY!$B$10,FORM!$B$2:$B459,G$2,FORM!$A$2:$A459,">"&$B16+0.5,FORM!$A$2:$A459,"<"&$B16+1.5)-sumifs(FORM!$D$2:$D459,FORM!$C$2:$C459,TODAY!$B$9,FORM!$B$2:$B459,G$2,FORM!$A$2:$A459,">"&$B16+0.5,FORM!$A$2:$A459,"<"&$B16+1.5) -> 0 | H16: =sumifs(FORM!$D$2:$D459,FORM!$C$2:$C459,TODAY!$B$10,FORM!$B$2:$B459,H$2,FORM!$A$2:$A459,">"&$B16+0.5,FORM!$A$2:$A459,"<"&$B16+1.5)-sumifs(FORM!$D$2:$D459,FORM!$C$2:$C459,TODAY!$B$9,FORM!$B$2:$B459,H$2,FORM!$A$2:$A459,">"&$B16+0.5,FORM!$A$2:$A459,"<"&$B16+1.5) -> -515 | I16: =sumifs(FORM!$D$2:$D459,FORM!$C$2:$C459,TODAY!$B$10,FORM!$B$2:$B459,I$2,FORM!$A$2:$A459,">"&$B16+0.5,FORM!$A$2:$A459,"<"&$B16+1.5)-sumifs(FORM!$D$2:$D459,FORM!$C$2:$C459,TODAY!$B$9,FORM!$B$2:$B459,I$2,FORM!$A$2:$A459,">"&$B16+0.5,FORM!$A$2:$A459,"<"&$B16+1.5) -> -195 | J16: =sumifs(FORM!$D$2:$D459,FORM!$C$2:$C459,TODAY!$B$10,FORM!$B$2:$B459,J$2,FORM!$A$2:$A459,">"&$B16+0.5,FORM!$A$2:$A459,"<"&$B16+1.5)-sumifs(FORM!$D$2:$D459,FORM!$C$2:$C459,TODAY!$B$9,FORM!$B$2:$B459,J$2,FORM!$A$2:$A459,">"&$B16+0.5,FORM!$A$2:$A459,"<"&$B16+1.5) -> 0 | K16: =sumifs(FORM!$D$2:$D459,FORM!$C$2:$C459,TODAY!$B$10,FORM!$B$2:$B459,K$2,FORM!$A$2:$A459,">"&$B16+0.5,FORM!$A$2:$A459,"<"&$B16+1.5)-sumifs(FORM!$D$2:$D459,FORM!$C$2:$C459,TODAY!$B$9,FORM!$B$2:$B459,K$2,FORM!$A$2:$A459,">"&$B16+0.5,FORM!$A$2:$A459,"<"&$B16+1.5) -> 0 | ... P16: =sumifs(FORM!$D$2:$D459,FORM!$C$2:$C459,TODAY!$B$10,FORM!$B$2:$B459,P$2,FORM!$A$2:$A459,">"&$B16+0.5,FORM!$A$2:$A459,"<"&$B16+1.5)-sumifs(FORM!$D$2:$D459,FORM!$C$2:$C459,TODAY!$B$9,FORM!$B$2:$B459,P$2,FORM!$A$2:$A459,">"&$B16+0.5,FORM!$A$2:$A459,"<"&$B16+1.5) -> 0 | Q16: 0 | R16: 0 | S16: 0 | T16: 0 | U16: =if(or($C16="",U$2=""),"",(sumifs(FORM!$D$2:$D459,FORM!$C$2:$C459,TODAY!$B$10,FORM!$B$2:$B459,U$2,FORM!$A$2:$A459,">"&$B16+0.5,FORM!$A$2:$A459,"<"&$B16+1.5)-sumifs(FORM!$D$2:$D459,FORM!$C$2:$C459,TODAY!$B$9,FORM!$B$2:$B459,U$2,FORM!$A$2:$A459,">"&$B16+0.5,FORM!$A$2:$A459,"<"&$B16+1.5))/$C16) -> 0
B17: 44932 | C17: 10 | D17: =sumifs(FORM!$D$2:$D459,FORM!$C$2:$C459,TODAY!$B$10,FORM!$B$2:$B459,D$2,FORM!$A$2:$A459,">"&$B17+0.5,FORM!$A$2:$A459,"<"&$B17+1.5)-sumifs(FORM!$D$2:$D459,FORM!$C$2:$C459,TODAY!$B$9,FORM!$B$2:$B459,D$2,FORM!$A$2:$A459,">"&$B17+0.5,FORM!$A$2:$A459,"<"&$B17+1.5) -> 240 | E17: =sumifs(FORM!$D$2:$D459,FORM!$C$2:$C459,TODAY!$B$10,FORM!$B$2:$B459,E$2,FORM!$A$2:$A459,">"&$B17+0.5,FORM!$A$2:$A459,"<"&$B17+1.5)-sumifs(FORM!$D$2:$D459,FORM!$C$2:$C459,TODAY!$B$9,FORM!$B$2:$B459,E$2,FORM!$A$2:$A459,">"&$B17+0.5,FORM!$A$2:$A459,"<"&$B17+1.5) -> -238 | F17: =sumifs(FORM!$D$2:$D459,FORM!$C$2:$C459,TODAY!$B$10,FORM!$B$2:$B459,F$2,FORM!$A$2:$A459,">"&$B17+0.5,FORM!$A$2:$A459,"<"&$B17+1.5)-sumifs(FORM!$D$2:$D459,FORM!$C$2:$C459,TODAY!$B$9,FORM!$B$2:$B459,F$2,FORM!$A$2:$A459,">"&$B17+0.5,FORM!$A$2:$A459,"<"&$B17+1.5) -> 191 | G17: =sumifs(FORM!$D$2:$D459,FORM!$C$2:$C459,TODAY!$B$10,FORM!$B$2:$B459,G$2,FORM!$A$2:$A459,">"&$B17+0.5,FORM!$A$2:$A459,"<"&$B17+1.5)-sumifs(FORM!$D$2:$D459,FORM!$C$2:$C459,TODAY!$B$9,FORM!$B$2:$B459,G$2,FORM!$A$2:$A459,">"&$B17+0.5,FORM!$A$2:$A459,"<"&$B17+1.5) -> 0 | H17: =sumifs(FORM!$D$2:$D459,FORM!$C$2:$C459,TODAY!$B$10,FORM!$B$2:$B459,H$2,FORM!$A$2:$A459,">"&$B17+0.5,FORM!$A$2:$A459,"<"&$B17+1.5)-sumifs(FORM!$D$2:$D459,FORM!$C$2:$C459,TODAY!$B$9,FORM!$B$2:$B459,H$2,FORM!$A$2:$A459,">"&$B17+0.5,FORM!$A$2:$A459,"<"&$B17+1.5) -> -193 | I17: =sumifs(FORM!$D$2:$D459,FORM!$C$2:$C459,TODAY!$B$10,FORM!$B$2:$B459,I$2,FORM!$A$2:$A459,">"&$B17+0.5,FORM!$A$2:$A459,"<"&$B17+1.5)-sumifs(FORM!$D$2:$D459,FORM!$C$2:$C459,TODAY!$B$9,FORM!$B$2:$B459,I$2,FORM!$A$2:$A459,">"&$B17+0.5,FORM!$A$2:$A459,"<"&$B17+1.5) -> 0 | J17: =sumifs(FORM!$D$2:$D459,FORM!$C$2:$C459,TODAY!$B$10,FORM!$B$2:$B459,J$2,FORM!$A$2:$A459,">"&$B17+0.5,FORM!$A$2:$A459,"<"&$B17+1.5)-sumifs(FORM!$D$2:$D459,FORM!$C$2:$C459,TODAY!$B$9,FORM!$B$2:$B459,J$2,FORM!$A$2:$A459,">"&$B17+0.5,FORM!$A$2:$A459,"<"&$B17+1.5) -> 0 | K17: =sumifs(FORM!$D$2:$D459,FORM!$C$2:$C459,TODAY!$B$10,FORM!$B$2:$B459,K$2,FORM!$A$2:$A459,">"&$B17+0.5,FORM!$A$2:$A459,"<"&$B17+1.5)-sumifs(FORM!$D$2:$D459,FORM!$C$2:$C459,TODAY!$B$9,FORM!$B$2:$B459,K$2,FORM!$A$2:$A459,">"&$B17+0.5,FORM!$A$2:$A459,"<"&$B17+1.5) -> 0 | ... P17: =sumifs(FORM!$D$2:$D459,FORM!$C$2:$C459,TODAY!$B$10,FORM!$B$2:$B459,P$2,FORM!$A$2:$A459,">"&$B17+0.5,FORM!$A$2:$A459,"<"&$B17+1.5)-sumifs(FORM!$D$2:$D459,FORM!$C$2:$C459,TODAY!$B$9,FORM!$B$2:$B459,P$2,FORM!$A$2:$A459,">"&$B17+0.5,FORM!$A$2:$A459,"<"&$B17+1.5) -> 0 | Q17: 0 | R17: 0 | S17: 0 | T17: 0 | U17: =if(or($C17="",U$2=""),"",(sumifs(FORM!$D$2:$D459,FORM!$C$2:$C459,TODAY!$B$10,FORM!$B$2:$B459,U$2,FORM!$A$2:$A459,">"&$B17+0.5,FORM!$A$2:$A459,"<"&$B17+1.5)-sumifs(FORM!$D$2:$D459,FORM!$C$2:$C459,TODAY!$B$9,FORM!$B$2:$B459,U$2,FORM!$A$2:$A459,">"&$B17+0.5,FORM!$A$2:$A459,"<"&$B17+1.5))/$C17) -> 0
B18: 44933 | C18: 10 | D18: =sumifs(FORM!$D$2:$D459,FORM!$C$2:$C459,TODAY!$B$10,FORM!$B$2:$B459,D$2,FORM!$A$2:$A459,">"&$B18+0.5,FORM!$A$2:$A459,"<"&$B18+1.5)-sumifs(FORM!$D$2:$D459,FORM!$C$2:$C459,TODAY!$B$9,FORM!$B$2:$B459,D$2,FORM!$A$2:$A459,">"&$B18+0.5,FORM!$A$2:$A459,"<"&$B18+1.5) -> -229 | E18: =sumifs(FORM!$D$2:$D459,FORM!$C$2:$C459,TODAY!$B$10,FORM!$B$2:$B459,E$2,FORM!$A$2:$A459,">"&$B18+0.5,FORM!$A$2:$A459,"<"&$B18+1.5)-sumifs(FORM!$D$2:$D459,FORM!$C$2:$C459,TODAY!$B$9,FORM!$B$2:$B459,E$2,FORM!$A$2:$A459,">"&$B18+0.5,FORM!$A$2:$A459,"<"&$B18+1.5) -> 479 | F18: =sumifs(FORM!$D$2:$D459,FORM!$C$2:$C459,TODAY!$B$10,FORM!$B$2:$B459,F$2,FORM!$A$2:$A459,">"&$B18+0.5,FORM!$A$2:$A459,"<"&$B18+1.5)-sumifs(FORM!$D$2:$D459,FORM!$C$2:$C459,TODAY!$B$9,FORM!$B$2:$B459,F$2,FORM!$A$2:$A459,">"&$B18+0.5,FORM!$A$2:$A459,"<"&$B18+1.5) -> 47 | G18: =sumifs(FORM!$D$2:$D459,FORM!$C$2:$C459,TODAY!$B$10,FORM!$B$2:$B459,G$2,FORM!$A$2:$A459,">"&$B18+0.5,FORM!$A$2:$A459,"<"&$B18+1.5)-sumifs(FORM!$D$2:$D459,FORM!$C$2:$C459,TODAY!$B$9,FORM!$B$2:$B459,G$2,FORM!$A$2:$A459,">"&$B18+0.5,FORM!$A$2:$A459,"<"&$B18+1.5) -> 0 | H18: =sumifs(FORM!$D$2:$D459,FORM!$C$2:$C459,TODAY!$B$10,FORM!$B$2:$B459,H$2,FORM!$A$2:$A459,">"&$B18+0.5,FORM!$A$2:$A459,"<"&$B18+1.5)-sumifs(FORM!$D$2:$D459,FORM!$C$2:$C459,TODAY!$B$9,FORM!$B$2:$B459,H$2,FORM!$A$2:$A459,">"&$B18+0.5,FORM!$A$2:$A459,"<"&$B18+1.5) -> -535 | I18: =sumifs(FORM!$D$2:$D459,FORM!$C$2:$C459,TODAY!$B$10,FORM!$B$2:$B459,I$2,FORM!$A$2:$A459,">"&$B18+0.5,FORM!$A$2:$A459,"<"&$B18+1.5)-sumifs(FORM!$D$2:$D459,FORM!$C$2:$C459,TODAY!$B$9,FORM!$B$2:$B459,I$2,FORM!$A$2:$A459,">"&$B18+0.5,FORM!$A$2:$A459,"<"&$B18+1.5) -> 0 | J18: =sumifs(FORM!$D$2:$D459,FORM!$C$2:$C459,TODAY!$B$10,FORM!$B$2:$B459,J$2,FORM!$A$2:$A459,">"&$B18+0.5,FORM!$A$2:$A459,"<"&$B18+1.5)-sumifs(FORM!$D$2:$D459,FORM!$C$2:$C459,TODAY!$B$9,FORM!$B$2:$B459,J$2,FORM!$A$2:$A459,">"&$B18+0.5,FORM!$A$2:$A459,"<"&$B18+1.5) -> 290 | K18: =sumifs(FORM!$D$2:$D459,FORM!$C$2:$C459,TODAY!$B$10,FORM!$B$2:$B459,K$2,FORM!$A$2:$A459,">"&$B18+0.5,FORM!$A$2:$A459,"<"&$B18+1.5)-sumifs(FORM!$D$2:$D459,FORM!$C$2:$C459,TODAY!$B$9,FORM!$B$2:$B459,K$2,FORM!$A$2:$A459,">"&$B18+0.5,FORM!$A$2:$A459,"<"&$B18+1.5) -> 0 | ... P18: =sumifs(FORM!$D$2:$D459,FORM!$C$2:$C459,TODAY!$B$10,FORM!$B$2:$B459,P$2,FORM!$A$2:$A459,">"&$B18+0.5,FORM!$A$2:$A459,"<"&$B18+1.5)-sumifs(FORM!$D$2:$D459,FORM!$C$2:$C459,TODAY!$B$9,FORM!$B$2:$B459,P$2,FORM!$A$2:$A459,">"&$B18+0.5,FORM!$A$2:$A459,"<"&$B18+1.5) -> 0 | Q18: 0 | R18: 0 | S18: 0 | T18: 0 | U18: =if(or($C18="",U$2=""),"",(sumifs(FORM!$D$2:$D459,FORM!$C$2:$C459,TODAY!$B$10,FORM!$B$2:$B459,U$2,FORM!$A$2:$A459,">"&$B18+0.5,FORM!$A$2:$A459,"<"&$B18+1.5)-sumifs(FORM!$D$2:$D459,FORM!$C$2:$C459,TODAY!$B$9,FORM!$B$2:$B459,U$2,FORM!$A$2:$A459,">"&$B18+0.5,FORM!$A$2:$A459,"<"&$B18+1.5))/$C18) -> 0
B19: 44939 | C19: 10 | D19: =sumifs(FORM!$D$2:$D459,FORM!$C$2:$C459,TODAY!$B$10,FORM!$B$2:$B459,D$2,FORM!$A$2:$A459,">"&$B19+0.5,FORM!$A$2:$A459,"<"&$B19+1.5)-sumifs(FORM!$D$2:$D459,FORM!$C$2:$C459,TODAY!$B$9,FORM!$B$2:$B459,D$2,FORM!$A$2:$A459,">"&$B19+0.5,FORM!$A$2:$A459,"<"&$B19+1.5) -> 256 | E19: =sumifs(FORM!$D$2:$D459,FORM!$C$2:$C459,TODAY!$B$10,FORM!$B$2:$B459,E$2,FORM!$A$2:$A459,">"&$B19+0.5,FORM!$A$2:$A459,"<"&$B19+1.5)-sumifs(FORM!$D$2:$D459,FORM!$C$2:$C459,TODAY!$B$9,FORM!$B$2:$B459,E$2,FORM!$A$2:$A459,">"&$B19+0.5,FORM!$A$2:$A459,"<"&$B19+1.5) -> -123 | F19: =sumifs(FORM!$D$2:$D459,FORM!$C$2:$C459,TODAY!$B$10,FORM!$B$2:$B459,F$2,FORM!$A$2:$A459,">"&$B19+0.5,FORM!$A$2:$A459,"<"&$B19+1.5)-sumifs(FORM!$D$2:$D459,FORM!$C$2:$C459,TODAY!$B$9,FORM!$B$2:$B459,F$2,FORM!$A$2:$A459,">"&$B19+0.5,FORM!$A$2:$A459,"<"&$B19+1.5) -> -100 | G19: =sumifs(FORM!$D$2:$D459,FORM!$C$2:$C459,TODAY!$B$10,FORM!$B$2:$B459,G$2,FORM!$A$2:$A459,">"&$B19+0.5,FORM!$A$2:$A459,"<"&$B19+1.5)-sumifs(FORM!$D$2:$D459,FORM!$C$2:$C459,TODAY!$B$9,FORM!$B$2:$B459,G$2,FORM!$A$2:$A459,">"&$B19+0.5,FORM!$A$2:$A459,"<"&$B19+1.5) -> 0 | H19: =sumifs(FORM!$D$2:$D459,FORM!$C$2:$C459,TODAY!$B$10,FORM!$B$2:$B459,H$2,FORM!$A$2:$A459,">"&$B19+0.5,FORM!$A$2:$A459,"<"&$B19+1.5)-sumifs(FORM!$D$2:$D459,FORM!$C$2:$C459,TODAY!$B$9,FORM!$B$2:$B459,H$2,FORM!$A$2:$A459,">"&$B19+0.5,FORM!$A$2:$A459,"<"&$B19+1.5) -> 320 | I19: =sumifs(FORM!$D$2:$D459,FORM!$C$2:$C459,TODAY!$B$10,FORM!$B$2:$B459,I$2,FORM!$A$2:$A459,">"&$B19+0.5,FORM!$A$2:$A459,"<"&$B19+1.5)-sumifs(FORM!$D$2:$D459,FORM!$C$2:$C459,TODAY!$B$9,FORM!$B$2:$B459,I$2,FORM!$A$2:$A459,">"&$B19+0.5,FORM!$A$2:$A459,"<"&$B19+1.5) -> 0 | J19: =sumifs(FORM!$D$2:$D459,FORM!$C$2:$C459,TODAY!$B$10,FORM!$B$2:$B459,J$2,FORM!$A$2:$A459,">"&$B19+0.5,FORM!$A$2:$A459,"<"&$B19+1.5)-sumifs(FORM!$D$2:$D459,FORM!$C$2:$C459,TODAY!$B$9,FORM!$B$2:$B459,J$2,FORM!$A$2:$A459,">"&$B19+0.5,FORM!$A$2:$A459,"<"&$B19+1.5) -> -353 | K19: =sumifs(FORM!$D$2:$D459,FORM!$C$2:$C459,TODAY!$B$10,FORM!$B$2:$B459,K$2,FORM!$A$2:$A459,">"&$B19+0.5,FORM!$A$2:$A459,"<"&$B19+1.5)-sumifs(FORM!$D$2:$D459,FORM!$C$2:$C459,TODAY!$B$9,FORM!$B$2:$B459,K$2,FORM!$A$2:$A459,">"&$B19+0.5,FORM!$A$2:$A459,"<"&$B19+1.5) -> 0 | ... P19: =sumifs(FORM!$D$2:$D459,FORM!$C$2:$C459,TODAY!$B$10,FORM!$B$2:$B459,P$2,FORM!$A$2:$A459,">"&$B19+0.5,FORM!$A$2:$A459,"<"&$B19+1.5)-sumifs(FORM!$D$2:$D459,FORM!$C$2:$C459,TODAY!$B$9,FORM!$B$2:$B459,P$2,FORM!$A$2:$A459,">"&$B19+0.5,FORM!$A$2:$A459,"<"&$B19+1.5) -> 0 | Q19: 0 | R19: 0 | S19: 0 | T19: 0 | U19: =if(or($C19="",U$2=""),"",(sumifs(FORM!$D$2:$D459,FORM!$C$2:$C459,TODAY!$B$10,FORM!$B$2:$B459,U$2,FORM!$A$2:$A459,">"&$B19+0.5,FORM!$A$2:$A459,"<"&$B19+1.5)-sumifs(FORM!$D$2:$D459,FORM!$C$2:$C459,TODAY!$B$9,FORM!$B$2:$B459,U$2,FORM!$A$2:$A459,">"&$B19+0.5,FORM!$A$2:$A459,"<"&$B19+1.5))/$C19) -> 0
B20: 44940 | C20: 1 | D20: =sumifs(FORM!$D$2:$D459,FORM!$C$2:$C459,TODAY!$B$10,FORM!$B$2:$B459,D$2,FORM!$A$2:$A459,">"&$B20+0.5,FORM!$A$2:$A459,"<"&$B20+1.5)-sumifs(FORM!$D$2:$D459,FORM!$C$2:$C459,TODAY!$B$9,FORM!$B$2:$B459,D$2,FORM!$A$2:$A459,">"&$B20+0.5,FORM!$A$2:$A459,"<"&$B20+1.5) -> 4260 | E20: =sumifs(FORM!$D$2:$D459,FORM!$C$2:$C459,TODAY!$B$10,FORM!$B$2:$B459,E$2,FORM!$A$2:$A459,">"&$B20+0.5,FORM!$A$2:$A459,"<"&$B20+1.5)-sumifs(FORM!$D$2:$D459,FORM!$C$2:$C459,TODAY!$B$9,FORM!$B$2:$B459,E$2,FORM!$A$2:$A459,">"&$B20+0.5,FORM!$A$2:$A459,"<"&$B20+1.5) -> 0 | F20: =sumifs(FORM!$D$2:$D459,FORM!$C$2:$C459,TODAY!$B$10,FORM!$B$2:$B459,F$2,FORM!$A$2:$A459,">"&$B20+0.5,FORM!$A$2:$A459,"<"&$B20+1.5)-sumifs(FORM!$D$2:$D459,FORM!$C$2:$C459,TODAY!$B$9,FORM!$B$2:$B459,F$2,FORM!$A$2:$A459,">"&$B20+0.5,FORM!$A$2:$A459,"<"&$B20+1.5) -> 200 | G20: =sumifs(FORM!$D$2:$D459,FORM!$C$2:$C459,TODAY!$B$10,FORM!$B$2:$B459,G$2,FORM!$A$2:$A459,">"&$B20+0.5,FORM!$A$2:$A459,"<"&$B20+1.5)-sumifs(FORM!$D$2:$D459,FORM!$C$2:$C459,TODAY!$B$9,FORM!$B$2:$B459,G$2,FORM!$A$2:$A459,">"&$B20+0.5,FORM!$A$2:$A459,"<"&$B20+1.5) -> 0 | H20: =sumifs(FORM!$D$2:$D459,FORM!$C$2:$C459,TODAY!$B$10,FORM!$B$2:$B459,H$2,FORM!$A$2:$A459,">"&$B20+0.5,FORM!$A$2:$A459,"<"&$B20+1.5)-sumifs(FORM!$D$2:$D459,FORM!$C$2:$C459,TODAY!$B$9,FORM!$B$2:$B459,H$2,FORM!$A$2:$A459,">"&$B20+0.5,FORM!$A$2:$A459,"<"&$B20+1.5) -> -2620 | I20: =sumifs(FORM!$D$2:$D459,FORM!$C$2:$C459,TODAY!$B$10,FORM!$B$2:$B459,I$2,FORM!$A$2:$A459,">"&$B20+0.5,FORM!$A$2:$A459,"<"&$B20+1.5)-sumifs(FORM!$D$2:$D459,FORM!$C$2:$C459,TODAY!$B$9,FORM!$B$2:$B459,I$2,FORM!$A$2:$A459,">"&$B20+0.5,FORM!$A$2:$A459,"<"&$B20+1.5) -> 0 | J20: =sumifs(FORM!$D$2:$D459,FORM!$C$2:$C459,TODAY!$B$10,FORM!$B$2:$B459,J$2,FORM!$A$2:$A459,">"&$B20+0.5,FORM!$A$2:$A459,"<"&$B20+1.5)-sumifs(FORM!$D$2:$D459,FORM!$C$2:$C459,TODAY!$B$9,FORM!$B$2:$B459,J$2,FORM!$A$2:$A459,">"&$B20+0.5,FORM!$A$2:$A459,"<"&$B20+1.5) -> 1350 | K20: =sumifs(FORM!$D$2:$D459,FORM!$C$2:$C459,TODAY!$B$10,FORM!$B$2:$B459,K$2,FORM!$A$2:$A459,">"&$B20+0.5,FORM!$A$2:$A459,"<"&$B20+1.5)-sumifs(FORM!$D$2:$D459,FORM!$C$2:$C459,TODAY!$B$9,FORM!$B$2:$B459,K$2,FORM!$A$2:$A459,">"&$B20+0.5,FORM!$A$2:$A459,"<"&$B20+1.5) -> 0 | ... P20: =sumifs(FORM!$D$2:$D459,FORM!$C$2:$C459,TODAY!$B$10,FORM!$B$2:$B459,P$2,FORM!$A$2:$A459,">"&$B20+0.5,FORM!$A$2:$A459,"<"&$B20+1.5)-sumifs(FORM!$D$2:$D459,FORM!$C$2:$C459,TODAY!$B$9,FORM!$B$2:$B459,P$2,FORM!$A$2:$A459,">"&$B20+0.5,FORM!$A$2:$A459,"<"&$B20+1.5) -> 0 | Q20: 0 | R20: 0 | S20: 0 | T20: 0 | U20: =if(or($C20="",U$2=""),"",(sumifs(FORM!$D$2:$D459,FORM!$C$2:$C459,TODAY!$B$10,FORM!$B$2:$B459,U$2,FORM!$A$2:$A459,">"&$B20+0.5,FORM!$A$2:$A459,"<"&$B20+1.5)-sumifs(FORM!$D$2:$D459,FORM!$C$2:$C459,TODAY!$B$9,FORM!$B$2:$B459,U$2,FORM!$A$2:$A459,">"&$B20+0.5,FORM!$A$2:$A459,"<"&$B20+1.5))/$C20) -> 0
B21: 44947 | C21: 10 | D21: =sumifs(FORM!$D$2:$D459,FORM!$C$2:$C459,TODAY!$B$10,FORM!$B$2:$B459,D$2,FORM!$A$2:$A459,">"&$B21+0.5,FORM!$A$2:$A459,"<"&$B21+1.5)-sumifs(FORM!$D$2:$D459,FORM!$C$2:$C459,TODAY!$B$9,FORM!$B$2:$B459,D$2,FORM!$A$2:$A459,">"&$B21+0.5,FORM!$A$2:$A459,"<"&$B21+1.5) -> 165 | E21: =sumifs(FORM!$D$2:$D459,FORM!$C$2:$C459,TODAY!$B$10,FORM!$B$2:$B459,E$2,FORM!$A$2:$A459,">"&$B21+0.5,FORM!$A$2:$A459,"<"&$B21+1.5)-sumifs(FORM!$D$2:$D459,FORM!$C$2:$C459,TODAY!$B$9,FORM!$B$2:$B459,E$2,FORM!$A$2:$A459,">"&$B21+0.5,FORM!$A$2:$A459,"<"&$B21+1.5) -> -200 | F21: =sumifs(FORM!$D$2:$D459,FORM!$C$2:$C459,TODAY!$B$10,FORM!$B$2:$B459,F$2,FORM!$A$2:$A459,">"&$B21+0.5,FORM!$A$2:$A459,"<"&$B21+1.5)-sumifs(FORM!$D$2:$D459,FORM!$C$2:$C459,TODAY!$B$9,FORM!$B$2:$B459,F$2,FORM!$A$2:$A459,">"&$B21+0.5,FORM!$A$2:$A459,"<"&$B21+1.5) -> 245 | G21: =sumifs(FORM!$D$2:$D459,FORM!$C$2:$C459,TODAY!$B$10,FORM!$B$2:$B459,G$2,FORM!$A$2:$A459,">"&$B21+0.5,FORM!$A$2:$A459,"<"&$B21+1.5)-sumifs(FORM!$D$2:$D459,FORM!$C$2:$C459,TODAY!$B$9,FORM!$B$2:$B459,G$2,FORM!$A$2:$A459,">"&$B21+0.5,FORM!$A$2:$A459,"<"&$B21+1.5) -> 55 | H21: =sumifs(FORM!$D$2:$D459,FORM!$C$2:$C459,TODAY!$B$10,FORM!$B$2:$B459,H$2,FORM!$A$2:$A459,">"&$B21+0.5,FORM!$A$2:$A459,"<"&$B21+1.5)-sumifs(FORM!$D$2:$D459,FORM!$C$2:$C459,TODAY!$B$9,FORM!$B$2:$B459,H$2,FORM!$A$2:$A459,">"&$B21+0.5,FORM!$A$2:$A459,"<"&$B21+1.5) -> -179 | I21: =sumifs(FORM!$D$2:$D459,FORM!$C$2:$C459,TODAY!$B$10,FORM!$B$2:$B459,I$2,FORM!$A$2:$A459,">"&$B21+0.5,FORM!$A$2:$A459,"<"&$B21+1.5)-sumifs(FORM!$D$2:$D459,FORM!$C$2:$C459,TODAY!$B$9,FORM!$B$2:$B459,I$2,FORM!$A$2:$A459,">"&$B21+0.5,FORM!$A$2:$A459,"<"&$B21+1.5) -> 63 | J21: =sumifs(FORM!$D$2:$D459,FORM!$C$2:$C459,TODAY!$B$10,FORM!$B$2:$B459,J$2,FORM!$A$2:$A459,">"&$B21+0.5,FORM!$A$2:$A459,"<"&$B21+1.5)-sumifs(FORM!$D$2:$D459,FORM!$C$2:$C459,TODAY!$B$9,FORM!$B$2:$B459,J$2,FORM!$A$2:$A459,">"&$B21+0.5,FORM!$A$2:$A459,"<"&$B21+1.5) -> 351 | K21: =sumifs(FORM!$D$2:$D459,FORM!$C$2:$C459,TODAY!$B$10,FORM!$B$2:$B459,K$2,FORM!$A$2:$A459,">"&$B21+0.5,FORM!$A$2:$A459,"<"&$B21+1.5)-sumifs(FORM!$D$2:$D459,FORM!$C$2:$C459,TODAY!$B$9,FORM!$B$2:$B459,K$2,FORM!$A$2:$A459,">"&$B21+0.5,FORM!$A$2:$A459,"<"&$B21+1.5) -> 0 | ... P21: =sumifs(FORM!$D$2:$D459,FORM!$C$2:$C459,TODAY!$B$10,FORM!$B$2:$B459,P$2,FORM!$A$2:$A459,">"&$B21+0.5,FORM!$A$2:$A459,"<"&$B21+1.5)-sumifs(FORM!$D$2:$D459,FORM!$C$2:$C459,TODAY!$B$9,FORM!$B$2:$B459,P$2,FORM!$A$2:$A459,">"&$B21+0.5,FORM!$A$2:$A459,"<"&$B21+1.5) -> 0 | Q21: 0 | R21: 0 | S21: 0 | T21: 0 | U21: =if(or($C21="",U$2=""),"",(sumifs(FORM!$D$2:$D459,FORM!$C$2:$C459,TODAY!$B$10,FORM!$B$2:$B459,U$2,FORM!$A$2:$A459,">"&$B21+0.5,FORM!$A$2:$A459,"<"&$B21+1.5)-sumifs(FORM!$D$2:$D459,FORM!$C$2:$C459,TODAY!$B$9,FORM!$B$2:$B459,U$2,FORM!$A$2:$A459,">"&$B21+0.5,FORM!$A$2:$A459,"<"&$B21+1.5))/$C21) -> 0
